Workbook

Sheet STUCT1
A1: No. | B1: Forecast? | C1: Ticket | D1: Node | E1: Name | F1: Parent | G1: Action | H1: STATUS | I1: STATUS Check | J1: Sector | K1: Comments | L1: SANITY | M1: Author
A2: 1 | B2: F0 | C2: No ticket | D2: G000001227 | E2: F34 HR - Fertility Reimbursement | F2: G000000589 | G2: New | H2: =IFERROR(VLOOKUP(Table2[[#This Row],[Ticket]],Okey!A:B,2,0),"") -> Ok | I2: Completed | J2: =VLOOKUP(Table2[[#This Row],[Author]],People!A:B,2,0) -> MGF | M2: Ronald Pierre Collado
A3: 2 | B3: F0 | C3: FR5620885 | D3: G000000431 | F3: G000000845 | G3: Move | H3: =IFERROR(VLOOKUP(Table2[[#This Row],[Ticket]],Okey!A:B,2,0),"") -> ok | I3: Completed | J3: =VLOOKUP(Table2[[#This Row],[Author]],People!A:B,2,0) -> MGF | M3: Nicolas Trautmann
A4: 3 | B4: F0 | C4: FR5684840 | D4: H000004347 | E4: SP Evobrutinib | F4: H000002092 | G4: New | H4: =IFERROR(VLOOKUP(Table2[[#This Row],[Ticket]],Okey!A:B,2,0),"") -> ok | I4: Completed | J4: =VLOOKUP(Table2[[#This Row],[Author]],People!A:B,2,0) -> HC | M4: Simone Oratovski
A5: 4 | B5: F0 | C5: FR5684840 | D5: H000004348 | E5: FF Evobrutinib | F5: H000002092 | G5: New | H5: =IFERROR(VLOOKUP(Table2[[#This Row],[Ticket]],Okey!A:B,2,0),"") -> ok | I5: Completed | J5: =VLOOKUP(Table2[[#This Row],[Author]],People!A:B,2,0) -> HC | M5: Simone Oratovski
A6: 5 | B6: F0 | C6: FR5684852 | D6: H000004349 | E6: SP Evobrutinib | F6: H000001807 | G6: New | H6: =IFERROR(VLOOKUP(Table2[[#This Row],[Ticket]],Okey!A:B,2,0),"") -> ok | I6: Completed | J6: =VLOOKUP(Table2[[#This Row],[Author]],People!A:B,2,0) -> HC | M6: Simone Oratovski
A7: 6 | B7: F0 | C7: FR5695335 | D7: H000004350 | E7: HC-BA-DX Centers of Excellence | F7: H000004177 | G7: New | H7: =IFERROR(VLOOKUP(Table2[[#This Row],[Ticket]],Okey!A:B,2,0),"") -> ok | I7: Completed | J7: =VLOOKUP(Table2[[#This Row],[Author]],People!A:B,2,0) -> MGF | M7: Joshua Cachola
A8: 7 | B8: F0 | C8: FR5695335 | D8: L000013599 | E8: LS-IT-B Business IT | F8: L000013388 | G8: New | H8: =IFERROR(VLOOKUP(Table2[[#This Row],[Ticket]],Okey!A:B,2,0),"") -> ok | I8: Completed | J8: =VLOOKUP(Table2[[#This Row],[Author]],People!A:B,2,0) -> MGF | M8: Joshua Cachola
A9: =1+A8 -> 8 | B9: F0 | C9: FR5695335 | D9: G000001123 | E9: EF-IT-ED Data Office for Enabling Functions | F9: G000000317 | G9: New | H9: =IFERROR(VLOOKUP(Table2[[#This Row],[Ticket]],Okey!A:B,2,0),"") -> ok | I9: Completed | J9: =VLOOKUP(Table2[[#This Row],[Author]],People!A:B,2,0) -> MGF | M9: Joshua Cachola
A10: =1+A9 -> 9 | B10: F0 | C10: FR5695335 | D10: G000001124 | E10: EF-IT-ES Data, Digital & IT - Site Mgmt & Patents | F10: G000000317 | G10: New | H10: =IFERROR(VLOOKUP(Table2[[#This Row],[Ticket]],Okey!A:B,2,0),"") -> ok | I10: Completed | J10: =VLOOKUP(Table2[[#This Row],[Author]],People!A:B,2,0) -> MGF | M10: Joshua Cachola
A11: =1+A10 -> 10 | B11: F0 | C11: FR5695335 | D11: G000001125 | E11: EF-IT-EC Key Capabilities | F11: G000000317 | G11: New | H11: =IFERROR(VLOOKUP(Table2[[#This Row],[Ticket]],Okey!A:B,2,0),"") -> ok | I11: Completed | J11: =VLOOKUP(Table2[[#This Row],[Author]],People!A:B,2,0) -> MGF | M11: Joshua Cachola
A12: =1+A11 -> 11 | B12: F0 | C12: FR5695335 | D12: G000001126 | E12: EF-IT-EM Sustainablity Management | F12: G000000317 | G12: New | H12: =IFERROR(VLOOKUP(Table2[[#This Row],[Ticket]],Okey!A:B,2,0),"") -> ok | I12: Completed | J12: =VLOOKUP(Table2[[#This Row],[Author]],People!A:B,2,0) -> MGF | M12: Joshua Cachola
A13: =1+A12 -> 12 | B13: F0 | C13: FR5695335 | D13: IT06031300 | E13: HC-BA-DX Centers of Excellence | F13: H000004350 | G13: New | H13: =IFERROR(VLOOKUP(Table2[[#This Row],[Ticket]],Okey!A:B,2,0),"") -> ok | I13: Completed | J13: =VLOOKUP(Table2[[#This Row],[Author]],People!A:B,2,0) -> MGF | M13: Joshua Cachola
A14: =1+A13 -> 13 | B14: F0 | C14: FR5695335 | D14: IT06051000 | E14: LS-IT-B Business IT | F14: L000013599 | G14: New | H14: =IFERROR(VLOOKUP(Table2[[#This Row],[Ticket]],Okey!A:B,2,0),"") -> ok | I14: Completed | J14: =VLOOKUP(Table2[[#This Row],[Author]],People!A:B,2,0) -> MGF | M14: Joshua Cachola
A15: =1+A14 -> 14 | B15: F0 | C15: FR5695335 | D15: IT06071400 | E15: EF-IT-ED Data Office for Enabling Functions | F15: G000001123 | G15: New | H15: =IFERROR(VLOOKUP(Table2[[#This Row],[Ticket]],Okey!A:B,2,0),"") -> ok | I15: Completed | J15: =VLOOKUP(Table2[[#This Row],[Author]],People!A:B,2,0) -> MGF | M15: Joshua Cachola
A16: =1+A15 -> 15 | B16: F0 | C16: FR5695335 | D16: IT06071500 | E16: EF-IT-ES Data, Digital & IT - Site Mgmt & Patents | F16: G000001124 | G16: New | H16: =IFERROR(VLOOKUP(Table2[[#This Row],[Ticket]],Okey!A:B,2,0),"") -> ok | I16: Completed | J16: =VLOOKUP(Table2[[#This Row],[Author]],People!A:B,2,0) -> MGF | M16: Joshua Cachola
A17: =1+A16 -> 16 | B17: F0 | C17: FR5695335 | D17: IT06071600 | E17: EF-IT-EC Key Capabilities | F17: G000001125 | G17: New | H17: =IFERROR(VLOOKUP(Table2[[#This Row],[Ticket]],Okey!A:B,2,0),"") -> ok | I17: Completed | J17: =VLOOKUP(Table2[[#This Row],[Author]],People!A:B,2,0) -> MGF | M17: Joshua Cachola
A18: =1+A17 -> 17 | B18: F0 | C18: FR5695335 | D18: IT06071700 | E18: EF-IT-EM Sustainablity Management | F18: G000001126 | G18: New | H18: =IFERROR(VLOOKUP(Table2[[#This Row],[Ticket]],Okey!A:B,2,0),"") -> ok | I18: Completed | J18: =VLOOKUP(Table2[[#This Row],[Author]],People!A:B,2,0) -> MGF | M18: Joshua Cachola
A19: =1+A18 -> 18 | B19: F0 | C19: FR5695357 | D19: IT06000000 | E19: EF-IT Information Technology | G19: Rename | H19: =IFERROR(VLOOKUP(Table2[[#This Row],[Ticket]],Okey!A:B,2,0),"") -> ok | I19: Completed | J19: =VLOOKUP(Table2[[#This Row],[Author]],People!A:B,2,0) -> MGF | M19: Joshua Cachola
A20: =1+A19 -> 19 | B20: F0 | C20: FR5695357 | D20: IT06010000 | E20: EF-IT-C Head Office & CISO | G20: Rename | H20: =IFERROR(VLOOKUP(Table2[[#This Row],[Ticket]],Okey!A:B,2,0),"") -> ok | I20: Completed | J20: =VLOOKUP(Table2[[#This Row],[Author]],People!A:B,2,0) -> MGF | M20: Joshua Cachola
A21: =1+A20 -> 20 | B21: F0 | C21: FR5695357 | D21: IT06020000 | E21: EF-IT-A Application Technology | G21: Rename | H21: =IFERROR(VLOOKUP(Table2[[#This Row],[Ticket]],Okey!A:B,2,0),"") -> ok | I21: Completed | J21: =VLOOKUP(Table2[[#This Row],[Author]],People!A:B,2,0) -> MGF | M21: Joshua Cachola
A22: =1+A21 -> 21 | B22: F0 | C22: FR5695357 | D22: IT06020100 | E22: EF-IT-AO Application Mgmt | G22: Rename | H22: =IFERROR(VLOOKUP(Table2[[#This Row],[Ticket]],Okey!A:B,2,0),"") -> ok | I22: Completed | J22: =VLOOKUP(Table2[[#This Row],[Author]],People!A:B,2,0) -> MGF | M22: Joshua Cachola
A23: =1+A22 -> 22 | B23: F0 | C23: FR5695357 | D23: IT06020300 | E23: EF-IT-AE ERP Next | G23: Rename | H23: =IFERROR(VLOOKUP(Table2[[#This Row],[Ticket]],Okey!A:B,2,0),"") -> ok | I23: Completed | J23: =VLOOKUP(Table2[[#This Row],[Author]],People!A:B,2,0) -> MGF | M23: Joshua Cachola
A24: =1+A23 -> 23 | B24: F0 | C24: FR5695357 | D24: IT06020600 | E24: EF-IT-AM Manufacturing, SCM & Quality | G24: Rename | H24: =IFERROR(VLOOKUP(Table2[[#This Row],[Ticket]],Okey!A:B,2,0),"") -> ok | I24: Completed | J24: =VLOOKUP(Table2[[#This Row],[Author]],People!A:B,2,0) -> MGF | M24: Joshua Cachola
A25: =1+A24 -> 24 | B25: F0 | C25: FR5695357 | D25: IT06020800 | E25: EF-IT-AR Apps R&D | G25: Rename | H25: =IFERROR(VLOOKUP(Table2[[#This Row],[Ticket]],Okey!A:B,2,0),"") -> ok | I25: Completed | J25: =VLOOKUP(Table2[[#This Row],[Author]],People!A:B,2,0) -> MGF | M25: Joshua Cachola
A26: =1+A25 -> 25 | B26: F0 | C26: FR5695357 | D26: IT06020900 | E26: EF-IT-AS Apps M&S | G26: Rename | H26: =IFERROR(VLOOKUP(Table2[[#This Row],[Ticket]],Okey!A:B,2,0),"") -> ok | I26: Completed | J26: =VLOOKUP(Table2[[#This Row],[Author]],People!A:B,2,0) -> MGF | M26: Joshua Cachola
A27: =1+A26 -> 26 | B27: F0 | C27: FR5695357 | D27: IT06021100 | E27: EF-IT-AA Corporate ERP Applications | G27: Rename | H27: =IFERROR(VLOOKUP(Table2[[#This Row],[Ticket]],Okey!A:B,2,0),"") -> ok | I27: Completed | J27: =VLOOKUP(Table2[[#This Row],[Author]],People!A:B,2,0) -> MGF | M27: Joshua Cachola
A28: =1+A27 -> 27 | B28: F0 | C28: FR5695357 | D28: IT06021200 | E28: EF-IT-AC Custom Apps & New Technology | G28: Rename | H28: =IFERROR(VLOOKUP(Table2[[#This Row],[Ticket]],Okey!A:B,2,0),"") -> ok | I28: Completed | J28: =VLOOKUP(Table2[[#This Row],[Author]],People!A:B,2,0) -> MGF | M28: Joshua Cachola
A29: =1+A28 -> 28 | B29: F0 | C29: FR5695357 | D29: IT06021300 | E29: EF-IT-AX Data Mgmt and Analytics | G29: Rename | H29: =IFERROR(VLOOKUP(Table2[[#This Row],[Ticket]],Okey!A:B,2,0),"") -> ok | I29: Completed | J29: =VLOOKUP(Table2[[#This Row],[Author]],People!A:B,2,0) -> MGF | M29: Joshua Cachola
A30: =1+A29 -> 29 | B30: F0 | C30: FR5695357 | D30: IT06021400 | E30: EF-IT-AT IT-Automation | G30: Rename | H30: =IFERROR(VLOOKUP(Table2[[#This Row],[Ticket]],Okey!A:B,2,0),"") -> ok | I30: Completed | J30: =VLOOKUP(Table2[[#This Row],[Author]],People!A:B,2,0) -> MGF | M30: Joshua Cachola
... A192: =1+A191 -> 191 | B192: F0 | C192: FR5714461 | D192: H000004349 | E192: IE - SP Evobrutinib | G192: Rename | H192: =IFERROR(VLOOKUP(Table2[[#This Row],[Ticket]],Okey!A:B,2,0),"") -> ok | I192: Completed | J192: =VLOOKUP(Table2[[#This Row],[Author]],People!A:B,2,0) -> HC | M192: Roland Earvin Combalicer
A193: =1+A192 -> 192 | B193: F0 | C193: FR5728795 | D193: G000000367 | F193: O000000009 | G193: Delete | H193: =IFERROR(VLOOKUP(Table2[[#This Row],[Ticket]],Okey!A:B,2,0),"") -> ok | I193: Completed | J193: =VLOOKUP(Table2[[#This Row],[Author]],People!A:B,2,0) -> MGF | M193: Marcus Morowski
A194: =1+A193 -> 193 | B194: F0 | C194: FR5728795 | D194: G000000368 | F194: O000000009 | G194: Delete | H194: =IFERROR(VLOOKUP(Table2[[#This Row],[Ticket]],Okey!A:B,2,0),"") -> ok | I194: Completed | J194: =VLOOKUP(Table2[[#This Row],[Author]],People!A:B,2,0) -> MGF | M194: Marcus Morowski
A195: =1+A194 -> 194 | B195: F0 | C195: FR5728795 | D195: G000000403 | F195: O000000009 | G195: Delete | H195: =IFERROR(VLOOKUP(Table2[[#This Row],[Ticket]],Okey!A:B,2,0),"") -> ok | I195: Completed | J195: =VLOOKUP(Table2[[#This Row],[Author]],People!A:B,2,0) -> MGF | M195: Marcus Morowski
A196: =1+A195 -> 195 | B196: F0 | C196: FR5728795 | D196: G000000405 | F196: O000000009 | G196: Delete | H196: =IFERROR(VLOOKUP(Table2[[#This Row],[Ticket]],Okey!A:B,2,0),"") -> ok | I196: Completed | J196: =VLOOKUP(Table2[[#This Row],[Author]],People!A:B,2,0) -> MGF | M196: Marcus Morowski
A197: =1+A196 -> 196 | B197: F0 | C197: FR5728795 | D197: G000000406 | F197: O000000009 | G197: Delete | H197: =IFERROR(VLOOKUP(Table2[[#This Row],[Ticket]],Okey!A:B,2,0),"") -> ok | I197: Completed | J197: =VLOOKUP(Table2[[#This Row],[Author]],People!A:B,2,0) -> MGF | M197: Marcus Morowski
A198: =1+A197 -> 197 | B198: F0 | C198: FR5728795 | D198: G000000407 | F198: O000000009 | G198: Delete | H198: =IFERROR(VLOOKUP(Table2[[#This Row],[Ticket]],Okey!A:B,2,0),"") -> ok | I198: Completed | J198: =VLOOKUP(Table2[[#This Row],[Author]],People!A:B,2,0) -> MGF | M198: Marcus Morowski
A199: =1+A198 -> 198 | B199: F0 | C199: FR5728795 | D199: G000000408 | F199: O000000009 | G199: Delete | H199: =IFERROR(VLOOKUP(Table2[[#This Row],[Ticket]],Okey!A:B,2,0),"") -> ok | I199: Completed | J199: =VLOOKUP(Table2[[#This Row],[Author]],People!A:B,2,0) -> MGF | M199: Marcus Morowski
A200: =1+A199 -> 199 | B200: F0 | C200: FR5728795 | D200: G000000409 | F200: O000000009 | G200: Delete | H200: =IFERROR(VLOOKUP(Table2[[#This Row],[Ticket]],Okey!A:B,2,0),"") -> ok | I200: Completed | J200: =VLOOKUP(Table2[[#This Row],[Author]],People!A:B,2,0) -> MGF | M200: Marcus Morowski
A201: =1+A200 -> 200 | B201: F0 | C201: FR5728795 | D201: L000009976 | F201: O000000009 | G201: Delete | H201: =IFERROR(VLOOKUP(Table2[[#This Row],[Ticket]],Okey!A:B,2,0),"") -> ok | I201: Completed | J201: =VLOOKUP(Table2[[#This Row],[Author]],People!A:B,2,0) -> MGF | M201: Marcus Morowski
...

Sheet Sheet11
A1: L000013817 | B1: L000013445
A2: L000013818 | B2: L000013417
A3: L000013819 | B3: L000006420
A4: L000013820 | B4: L000006420
A5: L000013821 | B5: L000013174
A6: L000013822 | B6: L000013174
A7: L000013823 | B7: L000013785
A8: L000006425 | B8: L000013819
A9: L000006429 | B9: L000013819
A10: L000006431 | B10: L000013820
A11: L000011451 | B11: L000013820
A12: L000007087 | B12: L000013821
... A40: L000006295 | B40: L000013685

Sheet Sheet10
A1: G000001191 | B1: MBS S&T - Business Process Management
A2: G000000392 | B2: SM-PT
A3: G000000389 | B3: SM-PM und PT
A4: G000000918 | B4: SM-PTT Material Management
A5: G000000919 | B5: SM-PTT Technical Warehouse
A6: P000000196 | B6: PG1 Blending+Packaging
A7: P000000197 | B7: PG2 Coating
A8: P000000198 | B8: PG1 Substrates
A9: L000005722 | B9: BM - Comm NA - South Pharma
A10: L000013350 | B10: CDMO - APAC Sales
A11: P000000001 | B11: EL-OP Optronics
A12: P000000002 | B12: EL-OP BU Head & Other
... A149: P000000331 | B149: Quality Gernsheim

Sheet Sheet9
A1: G000000994 | B1: G000000529
A2: G000000995 | B2: G000000529
A3: G000000993 | B3: G000000873
A4: G000001357 | B4: G000001146
A5: G000001191 | B5: G000001146
A6: G000000511 | B6: G000000873
A7: G000000512 | B7: G000000873
A8: G000000513 | B8: G000000873
A9: G000000514 | B9: G000000873
A10: G000001007 | B10: G000000873
A11: G000001065 | B11: G000000873
A12: G000001066 | B12: G000000873
... A149: P000000331 | B149: P000000330

Sheet Sheet7
A1: KR00 | I1: KR00
A2: G000001357 | B2: MBS S&T Learning & Develop., Knwldg Mgt | C2: X | I2: G000001146 | J2: G000001357
A3: G000001191 | B3: MBS S&T - Business Process Management | C3: X | I3: G000001143 | J3: G000001358
A4: G000000392 | B4: SM-PT | C4: X | I4: P000000001 | J4: P000001254
A5: G000000389 | B5: SM-PM und PT | C5: X | I5: P000001254 | J5: P000001255
A6: G000000918 | B6: SM-PTT Material Management | C6: X | I6: P000001254 | J6: P000001256
A7: G000000919 | B7: SM-PTT Technical Warehouse | C7: X | I7: P000001254 | J7: P000001257
A8: G000000387 | B8: SM-PM | C8: X | I8: P000001254 | J8: P000001258
A9: G000000391 | B9: SM-PMA | C9: X | I9: P000000024 | J9: P000001259
A10: P000000196 | B10: PG1 Blending+Packaging | C10: X | I10: P000001259 | J10: P000001260
A11: P000000197 | B11: PG2 Coating | C11: X | I11: P000001259 | J11: P000001261
A12: P000000198 | B12: PG1 Substrates | C12: X | I12: P000001259 | J12: P000001262
A13: G000001358 | B13: GMV MBS Hub Wroclaw - ABP | C13: X | I13: P000001259 | J13: P000001263
... A17: P000001257 | B17: EL-OP-M M&I Operations | C17: X | I17: P000000590 | J17: P000001267
A18: P000001258 | B18: EL-OP-M M&I R&D | C18: X | O18: L000013595
A19: P000000001 | B19: EL-OP Optronics | C19: X | O19: L000013595
A20: P000000002 | B20: EL-OP BU Head & Other | C20: X
A21: P000000695 | B21: EL-OP BU head Organization | C21: X
A22: P000000696 | B22: EL-OP Inventor Remuneration | C22: X
A23: P000000697 | B23: EL-OP Intangible Assets | C23: X
A24: P000000698 | B24: EL-OP Other | C24: X
A25: P000000022 | B25: EL-OP-W LC Windows | C25: X
A26: P000000055 | B26: EL-OP-S Supply Chain Optronics | C26: X
A27: P000000505 | B27: Optronics Production Sites | C27: X
A28: P000000056 | B28: EL-OP-SD Site Darmstadt, Germany | C28: X
A29: P000001172 | B29: EL-OP-SDPP Production Planning | C29: X
A30: P000000087 | B30: EL-OP-SA Site Atsugi, Japan | C30: X
A31: P000000097 | B31: EL-OP-SZ Site Suzhou, China | C31: X
A32: P000000107 | B32: EL-OP-ST Site Taoyuan, Taiwan | C32: X | H32: 1000
A33: P000000117 | B33: EL-OP-SH Site Hsinchu, Taiwan | C33: X | H33: L000013824 | I33: mRNA CDMO QAO | J33: X | K33: X | L33: X | M33: X | N33: X
A34: P000000127 | B34: EL-OP-SP Site Poseung, S. Korea | C34: X | H34: L000013825 | I34: mRNA CDMO Support Functions | J34: X | K34: X | L34: X | M34: X | N34: X
A35: P000000137 | B35: EL-OP-SS Site Shanghai, China | C35: X | H35: P000000331 | I35: Quality Gernsheim | J35: X | K35: X | L35: X | M35: X | N35: X
A36: P000000506 | B36: EL-OP-SC Supply Chain Excellence | C36: X
A37: P000000507 | B37: EL-OP-SQ QA Optronics | C37: X
A38: P000001167 | B38: EL-OP-SG Global Demand & Supply Planning | C38: X
A39: P000001168 | B39: EL-OP-SV Value Stream Mngt | C39: X
A40: P000001109 | B40: EL-OP-L LC/DPM] | C40: X
A41: P000001110 | B41: EL-OP-LC LC/DPM Sales CN | C41: X
A42: P000001111 | B42: EL-OP-LT LC/DPM Sales TW & JP | C42: X
A43: P000001112 | B43: EL-OP-LM LC/DPM Marketing | C43: X
...

Sheet Sheet6
A1: 1000
A2: G000001146 | B2: G000001357
A3: L000013445 | B3: L000013817
A4: L000013417 | B4: L000013818
A5: L000006420 | B5: L000013819
A6: L000006420 | B6: L000013820
A7: L000013174 | B7: L000013821
A8: L000013174 | B8: L000013822
A9: L000013785 | B9: L000013823
A10: G000001143 | B10: G000001358
A11: P000000001 | B11: P000001254
A12: P000001254 | B12: P000001255
A13: P000001254 | B13: P000001256
... A24: P000000590 | B24: P000001267

Sheet Sheet5
A1: 25014377
A2: 25014151

Sheet Sheet4
A1: 1000
A2: G000001357 | B2: MBS S&T Learning & Develop., Knwldg Mgt | C2: X | D2: X | E2: X | F2: X | G2: X
A3: G000001191 | B3: MBS S&T - Business Process Management | C3: X | D3: X | E3: X | F3: X | G3: X
A4: G000000392 | B4: SM-PT | C4: X | D4: X | E4: X | F4: X | G4: X
A5: G000000389 | B5: SM-PM und PT | C5: X | D5: X | E5: X | F5: X | G5: X
A6: G000000918 | B6: SM-PTT Material Management | C6: X | D6: X | E6: X | F6: X | G6: X
A7: G000000919 | B7: SM-PTT Technical Warehouse | C7: X | D7: X | E7: X | F7: X | G7: X
A8: G000000919 | B8: SM-PTT IVV Allocation CCs | C8: X | D8: X | E8: X | F8: X | G8: X
A9: G000000387 | B9: SM-PM | C9: X | D9: X | E9: X | F9: X | G9: X
A10: G000000391 | B10: SM-PMA | C10: X | D10: X | E10: X | F10: X | G10: X
A11: P000000196 | B11: PG1 Blending+Packaging | C11: X | D11: X | E11: X | F11: X | G11: X
A12: P000000197 | B12: PG2 Coating | C12: X | D12: X | E12: X | F12: X | G12: X
A13: P000000198 | B13: PG1 Substrates | C13: X | D13: X | E13: X | F13: X | G13: X
... A141: P000001267 | B141: Licrivision | C141: X | D141: X | E141: X | F141: X | G141: X

Sheet Sheet3
B1: 1000
B2: G000000359 | C2: SM-H Site & HQ Development Services | D2: X | E2: X | F2: X | G2: X | H2: X
B4: KR00
B5: G000000359 | C5: SM-H Site & HQ Development Services | D5: X

Sheet Sheet2
A1: 1000
A2: G000001356 | B2: EF-IT-PX | C2: X | D2: X | E2: X | F2: X | G2: X
A3: IT06100900 | B3: EF-IT-PX | C3: X | D3: X | E3: X | F3: X | G3: X
A5: KR00
A6: G000001356 | B6: EF-IT-PX | C6: X
A7: IT06100900 | B7: EF-IT-PX | C7: X
A10: 1000
A11: G000000340 | B11: G000001356
A12: G000001356 | B12: IT06100900
A14: Kr00
A15: G000000340 | B15: G000001356
A16: G000001356 | B16: IT06100900

Sheet Sheet1
A1: 1000
A2: G000001281 | B2: GPA PS - Core Ext.Cost | C2: X | D2: X | E2: X | F2: X | G2: X
A3: G000001282 | B3: GPB PS - Healthcare Ext.Cost | C3: X | D3: X | E3: X | F3: X | G3: X
A4: G000001283 | B4: GPC PS - Life Science Ext.Cost | C4: X | D4: X | E4: X | F4: X | G4: X
A5: G000001284 | B5: GPD PS - Electronics Ext.Cost | C5: X | D5: X | E5: X | F5: X | G5: X
A7: KR00
A8: G000001281 | B8: GPA PS - Core Ext.Cost | C8: X
A9: G000001282 | B9: GPB PS - Healthcare Ext.Cost | C9: X
A10: G000001283 | B10: GPC PS - Life Science Ext.Cost | C10: X
A11: G000001284 | B11: GPD PS - Electronics Ext.Cost | C11: X

Sheet People
A1: Opened By | B1: Sector
A2: Joshua Cachola | B2: MGF
A3: Simone Oratovski | B3: HC
A4: Nicolas Trautmann | B4: MGF
A5: Henry Ifurung Jr. | B5: HC
A6: Phoebe Anne Fortaleza | B6: LS
A7: Joebeth Navarro | B7: HC
A8: Paul Kopp | B8: MGF
A9: Maureen Cardano | B9: HC
A10: Roland Earvin Combalicer | B10: HC
A11: Marcus Morowski | B11: MGF
A12: Megan Wang | B12: MGF
... A47: Gerhard Doeller | B47: EL

Sheet 2023
A1: No. | B1: Forecast? | C1: Ticket | D1: Node | E1: Name | F1: Parent | G1: Action | H1: STATUS | I1: STATUS Check | J1: Sector | K1: Comments | L1: SANITY | M1: Author
A2: 1 | B2: F1 | C2: FR5068879 | D2: L000011515 | F2: O000000009 | G2: Delete | H2: =IFERROR(VLOOKUP(Table2[[#This Row],[Ticket]],Okey!A:B,2,0),"") -> Ok | I2: Closed | J2: =VLOOKUP(Table2[[#This Row],[Author]],People!A:B,2,0) -> MGF | M2: Phoebe Anne Fortaleza
A3: =1+A2 -> 2 | B3: F1 | C3: FR5068879 | D3: L000013398 | E3: BioVV - Quality & Regulatory -G | F3: L000006935 | G3: New | H3: =IFERROR(VLOOKUP(Table2[[#This Row],[Ticket]],Okey!A:B,2,0),"") -> ok | I3: Closed | J3: =VLOOKUP(Table2[[#This Row],[Author]],People!A:B,2,0) -> MGF | M3: Phoebe Anne Fortaleza
A4: =1+A3 -> 3 | B4: F1 | C4: FR5072548 | D4: G000000958 | F4: G000000955 | G4: Move | H4: =IFERROR(VLOOKUP(Table2[[#This Row],[Ticket]],Okey!A:B,2,0),"") -> ok | I4: Closed | J4: =VLOOKUP(Table2[[#This Row],[Author]],People!A:B,2,0) -> HC | M4: Nadine Anic
A5: =1+A4 -> 4 | B5: F1 | C5: FR5072548 | D5: G000000959 | F5: G000000958 | G5: Move | H5: =IFERROR(VLOOKUP(Table2[[#This Row],[Ticket]],Okey!A:B,2,0),"") -> ok | I5: Closed | J5: =VLOOKUP(Table2[[#This Row],[Author]],People!A:B,2,0) -> HC | M5: Nadine Anic
A6: =1+A5 -> 5 | B6: F1 | C6: FR5072548 | D6: G000000960 | F6: G000000958 | G6: Move | H6: =IFERROR(VLOOKUP(Table2[[#This Row],[Ticket]],Okey!A:B,2,0),"") -> ok | I6: Closed | J6: =VLOOKUP(Table2[[#This Row],[Author]],People!A:B,2,0) -> HC | M6: Nadine Anic
A7: =1+A6 -> 6 | B7: F1 | C7: FR5072548 | D7: G000000961 | F7: G000000958 | G7: Move | H7: =IFERROR(VLOOKUP(Table2[[#This Row],[Ticket]],Okey!A:B,2,0),"") -> ok | I7: Closed | J7: =VLOOKUP(Table2[[#This Row],[Author]],People!A:B,2,0) -> MGF | M7: Nadine Anic
A8: =1+A7 -> 7 | B8: F1 | C8: FR5072548 | D8: G000000962 | F8: G000000958 | G8: Move | H8: =IFERROR(VLOOKUP(Table2[[#This Row],[Ticket]],Okey!A:B,2,0),"") -> ok | I8: Closed | J8: =VLOOKUP(Table2[[#This Row],[Author]],People!A:B,2,0) -> MGF | M8: Nadine Anic
A9: =1+A8 -> 8 | B9: F1 | C9: FR5072548 | D9: G000000963 | F9: G000000958 | G9: Move | H9: =IFERROR(VLOOKUP(Table2[[#This Row],[Ticket]],Okey!A:B,2,0),"") -> ok | I9: Closed | J9: =VLOOKUP(Table2[[#This Row],[Author]],People!A:B,2,0) -> MGF | M9: Nadine Anic
A10: =1+A9 -> 9 | B10: F1 | C10: FR5072548 | D10: G000000964 | F10: G000000958 | G10: Move | H10: =IFERROR(VLOOKUP(Table2[[#This Row],[Ticket]],Okey!A:B,2,0),"") -> ok | I10: Closed | J10: =VLOOKUP(Table2[[#This Row],[Author]],People!A:B,2,0) -> MGF | M10: Nadine Anic
A11: =1+A10 -> 10 | B11: F1 | C11: FR5072548 | D11: G000000965 | F11: G000000958 | G11: Move | H11: =IFERROR(VLOOKUP(Table2[[#This Row],[Ticket]],Okey!A:B,2,0),"") -> ok | I11: Closed | J11: =VLOOKUP(Table2[[#This Row],[Author]],People!A:B,2,0) -> MGF | M11: Nadine Anic
A12: =1+A11 -> 11 | B12: F1 | C12: FR5072548 | D12: G000000966 | F12: G000000955 | G12: Move | H12: =IFERROR(VLOOKUP(Table2[[#This Row],[Ticket]],Okey!A:B,2,0),"") -> ok | I12: Closed | J12: =VLOOKUP(Table2[[#This Row],[Author]],People!A:B,2,0) -> MGF | M12: Nadine Anic
A13: =1+A12 -> 12 | B13: F1 | C13: FR5072548 | D13: G000000967 | F13: G000000956 | G13: Move | H13: =IFERROR(VLOOKUP(Table2[[#This Row],[Ticket]],Okey!A:B,2,0),"") -> ok | I13: Closed | J13: =VLOOKUP(Table2[[#This Row],[Author]],People!A:B,2,0) -> MGF | M13: Nadine Anic
A14: =1+A13 -> 13 | B14: F1 | C14: FR5072548 | D14: G000000968 | F14: G000000967 | G14: Move | H14: =IFERROR(VLOOKUP(Table2[[#This Row],[Ticket]],Okey!A:B,2,0),"") -> ok | I14: Closed | J14: =VLOOKUP(Table2[[#This Row],[Author]],People!A:B,2,0) -> MGF | M14: Nadine Anic
A15: =1+A14 -> 14 | B15: F1 | C15: FR5072548 | D15: G000000969 | F15: G000000967 | G15: Move | H15: =IFERROR(VLOOKUP(Table2[[#This Row],[Ticket]],Okey!A:B,2,0),"") -> ok | I15: Closed | J15: =VLOOKUP(Table2[[#This Row],[Author]],People!A:B,2,0) -> MGF | M15: Nadine Anic
... A41: =1+A40 -> 40 | B41: F1 | C41: FR5072548 | D41: G000000995 | F41: G000000993 | G41: Move | H41: =IFERROR(VLOOKUP(Table2[[#This Row],[Ticket]],Okey!A:B,2,0),"") -> ok | I41: Closed | J41: =VLOOKUP(Table2[[#This Row],[Author]],People!A:B,2,0) -> MGF | M41: Nadine Anic
A42: =1+A41 -> 41 | B42: F1 | C42: FR5082089 | D42: G000000461 | E42: SM-B Strategy Realization & Enablement | G42: Rename | H42: =IFERROR(VLOOKUP(Table2[[#This Row],[Ticket]],Okey!A:B,2,0),"") -> ok | I42: Closed | J42: =VLOOKUP(Table2[[#This Row],[Author]],People!A:B,2,0) -> MGF | M42: Sybille Rogmans
A43: =1+A42 -> 42 | B43: F1 | C43: FR5082089 | D43: G000000462 | E43: SM-B Strategy Realization & Enablement | G43: Rename | H43: =IFERROR(VLOOKUP(Table2[[#This Row],[Ticket]],Okey!A:B,2,0),"") -> ok | I43: Closed | J43: =VLOOKUP(Table2[[#This Row],[Author]],People!A:B,2,0) -> MGF | M43: Sybille Rogmans
A44: =1+A43 -> 43 | B44: F1 | C44: FR5082089 | D44: G000000463 | E44: SM-BB Business Excellence | G44: Rename | H44: =IFERROR(VLOOKUP(Table2[[#This Row],[Ticket]],Okey!A:B,2,0),"") -> ok | I44: Closed | J44: =VLOOKUP(Table2[[#This Row],[Author]],People!A:B,2,0) -> MGF | M44: Sybille Rogmans
A45: =1+A44 -> 44 | B45: F1 | C45: FR5082089 | D45: G000000464 | E45: SM-BS Strategy Realization | G45: Rename | H45: =IFERROR(VLOOKUP(Table2[[#This Row],[Ticket]],Okey!A:B,2,0),"") -> ok | I45: Closed | J45: =VLOOKUP(Table2[[#This Row],[Author]],People!A:B,2,0) -> MGF | M45: Sybille Rogmans
A46: =1+A45 -> 45 | B46: F1 | C46: FR5082089 | D46: G000000466 | E46: SM-BC Strategic Contracting | G46: Rename | H46: =IFERROR(VLOOKUP(Table2[[#This Row],[Ticket]],Okey!A:B,2,0),"") -> ok | I46: Closed | J46: =VLOOKUP(Table2[[#This Row],[Author]],People!A:B,2,0) -> MGF | M46: Sybille Rogmans
A47: =1+A46 -> 46 | B47: F1 | C47: FR5082089 | D47: G000000470 | E47: SM-BQ dummy 6 | G47: Rename | H47: =IFERROR(VLOOKUP(Table2[[#This Row],[Ticket]],Okey!A:B,2,0),"") -> ok | I47: Closed | J47: =VLOOKUP(Table2[[#This Row],[Author]],People!A:B,2,0) -> MGF | M47: Sybille Rogmans
A48: =1+A47 -> 47 | B48: F1 | C48: FR5082089 | D48: G000000473 | E48: SM-BD Data & Digital Enablement | G48: Rename | H48: =IFERROR(VLOOKUP(Table2[[#This Row],[Ticket]],Okey!A:B,2,0),"") -> ok | I48: Closed | J48: =VLOOKUP(Table2[[#This Row],[Author]],People!A:B,2,0) -> MGF | M48: Sybille Rogmans
A49: =1+A48 -> 48 | B49: F1 | C49: FR5082089 | D49: G000000868 | E49: SM-BP People, Change & Comms | G49: Rename | H49: =IFERROR(VLOOKUP(Table2[[#This Row],[Ticket]],Okey!A:B,2,0),"") -> ok | I49: Closed | J49: =VLOOKUP(Table2[[#This Row],[Author]],People!A:B,2,0) -> MGF | M49: Sybille Rogmans
A50: =1+A49 -> 49 | B50: F1 | C50: FR5082089 | D50: G000000471 | E50: SM-BQ Quality Management | F50: G000000470 | G50: Rename/Move | H50: =IFERROR(VLOOKUP(Table2[[#This Row],[Ticket]],Okey!A:B,2,0),"") -> ok | I50: Closed | J50: =VLOOKUP(Table2[[#This Row],[Author]],People!A:B,2,0) -> MGF | M50: Sybille Rogmans
A51: =1+A50 -> 50 | B51: F1 | C51: FR5092977 | D51: G000000355 | E51: SM Site Management | G51: Rename | H51: =IFERROR(VLOOKUP(Table2[[#This Row],[Ticket]],Okey!A:B,2,0),"") -> ok | I51: Closed | J51: =VLOOKUP(Table2[[#This Row],[Author]],People!A:B,2,0) -> MGF | M51: Nicolas Trautmann
A52: =1+A51 -> 51 | B52: F1 | C52: FR5092977 | D52: G000000359 | E52: SM-H Strategy & Transform. | G52: Rename | H52: =IFERROR(VLOOKUP(Table2[[#This Row],[Ticket]],Okey!A:B,2,0),"") -> ok | I52: Closed | J52: =VLOOKUP(Table2[[#This Row],[Author]],People!A:B,2,0) -> MGF | M52: Nicolas Trautmann
A53: =1+A52 -> 52 | B53: F1 | C53: FR5092977 | D53: G000000365 | E53: SM-A Analytical Services | G53: Rename | H53: =IFERROR(VLOOKUP(Table2[[#This Row],[Ticket]],Okey!A:B,2,0),"") -> ok | I53: Closed | J53: =VLOOKUP(Table2[[#This Row],[Author]],People!A:B,2,0) -> MGF | M53: Nicolas Trautmann
A54: =1+A53 -> 53 | B54: F1 | C54: FR5092977 | D54: G000000372 | E54: SM-E Engineering Services | G54: Rename | H54: =IFERROR(VLOOKUP(Table2[[#This Row],[Ticket]],Okey!A:B,2,0),"") -> ok | I54: Closed | J54: =VLOOKUP(Table2[[#This Row],[Author]],People!A:B,2,0) -> MGF | M54: Nicolas Trautmann
A55: =1+A54 -> 54 | B55: F1 | C55: FR5092977 | D55: G000000410 | E55: SM-U | G55: Rename | H55: =IFERROR(VLOOKUP(Table2[[#This Row],[Ticket]],Okey!A:B,2,0),"") -> ok | I55: Closed | J55: =VLOOKUP(Table2[[#This Row],[Author]],People!A:B,2,0) -> MGF | M55: Nicolas Trautmann
A56: =1+A55 -> 55 | B56: F1 | C56: FR5092977 | D56: G000000439 | E56: SM-Verrechnungen / Sachkosten | G56: Rename | H56: =IFERROR(VLOOKUP(Table2[[#This Row],[Ticket]],Okey!A:B,2,0),"") -> ok | I56: Closed | J56: =VLOOKUP(Table2[[#This Row],[Author]],People!A:B,2,0) -> MGF | M56: Nicolas Trautmann
A57: =1+A56 -> 56 | B57: F1 | C57: FR5092977 | D57: G000000890 | E57: SM-HG Fluxum | G57: Rename | H57: =IFERROR(VLOOKUP(Table2[[#This Row],[Ticket]],Okey!A:B,2,0),"") -> ok | I57: Closed | J57: =VLOOKUP(Table2[[#This Row],[Author]],People!A:B,2,0) -> MGF | M57: Nicolas Trautmann
A58: =1+A57 -> 57 | B58: F1 | C58: FR5092977 | D58: G000000360 | E58: SM-HF Future | G58: Rename | H58: =IFERROR(VLOOKUP(Table2[[#This Row],[Ticket]],Okey!A:B,2,0),"") -> ok | I58: Closed | J58: =VLOOKUP(Table2[[#This Row],[Author]],People!A:B,2,0) -> MGF | M58: Nicolas Trautmann
A59: =1+A58 -> 58 | B59: F1 | C59: FR5092977 | D59: G000000361 | E59: DA Goes Global | G59: Rename | H59: =IFERROR(VLOOKUP(Table2[[#This Row],[Ticket]],Okey!A:B,2,0),"") -> ok | I59: Closed | J59: =VLOOKUP(Table2[[#This Row],[Author]],People!A:B,2,0) -> MGF | M59: Nicolas Trautmann
A60: =1+A59 -> 59 | B60: F1 | C60: FR5092977 | D60: G000000362 | E60: SM-HM Marketing&Dialog | G60: Rename | H60: =IFERROR(VLOOKUP(Table2[[#This Row],[Ticket]],Okey!A:B,2,0),"") -> ok | I60: Closed | J60: =VLOOKUP(Table2[[#This Row],[Author]],People!A:B,2,0) -> MGF | M60: Nicolas Trautmann
A61: =1+A60 -> 60 | B61: F1 | C61: FR5092977 | D61: G000000888 | E61: SM-HR HQ Relations & Mgmt of | G61: Rename | H61: =IFERROR(VLOOKUP(Table2[[#This Row],[Ticket]],Okey!A:B,2,0),"") -> ok | I61: Closed | J61: =VLOOKUP(Table2[[#This Row],[Author]],People!A:B,2,0) -> MGF | M61: Nicolas Trautmann
A62: =1+A61 -> 61 | B62: F1 | C62: FR5092977 | D62: G000000889 | E62: SM-HP Plattforms | G62: Rename | H62: =IFERROR(VLOOKUP(Table2[[#This Row],[Ticket]],Okey!A:B,2,0),"") -> ok | I62: Closed | J62: =VLOOKUP(Table2[[#This Row],[Author]],People!A:B,2,0) -> MGF | M62: Nicolas Trautmann
... A207: =1+A206 -> 206 | B207: F1 | C207: FR5092977 | D207: G000000416 | E207: SM-SCC Conference & Catering | G207: Rename | H207: =IFERROR(VLOOKUP(Table2[[#This Row],[Ticket]],Okey!A:B,2,0),"") -> ok | I207: Closed | J207: =VLOOKUP(Table2[[#This Row],[Author]],People!A:B,2,0) -> MGF | M207: Nicolas Trautmann
A208: =1+A207 -> 207 | B208: F1 | C208: FR5099062 | D208: H000004191 | E208: Medical - Local R&D | F208: H000000447 | G208: New | H208: =IFERROR(VLOOKUP(Table2[[#This Row],[Ticket]],Okey!A:B,2,0),"") -> ok | I208: Closed | J208: =VLOOKUP(Table2[[#This Row],[Author]],People!A:B,2,0) -> MGF | M208: Megan Wang
A209: =1+A208 -> 208 | B209: F1 | C209: FR5107986 | D209: H000000813 | E209: CMS International | G209: Rename | H209: =IFERROR(VLOOKUP(Table2[[#This Row],[Ticket]],Okey!A:B,2,0),"") -> ok | I209: Closed | J209: =VLOOKUP(Table2[[#This Row],[Author]],People!A:B,2,0) -> MGF | M209: Marlon Abadia
...

Sheet Sectors
A1: P | B1: Electronics
A2: L | B2: Life Science
A3: H | B3: Healthcare
A4: G | B4: MGF
A5: O | B5: No known

Sheet Okey
A1: FR5208660 | B1: Ok
A2: FR5265964 | B2: Ok
A3: FR5266249 | B3: Ok
A4: FR5267957 | B4: Ok
A5: FR5267969 | B5: Ok
A6: FR5286834 | B6: Ok
A7: FR5068879 | B7: Ok
A8: FR5072548 | B8: Ok
A9: FR5082089 | B9: Ok
A10: FR5092977 | B10: Ok
A11: FR5099062 | B11: Ok
A12: FR5107986 | B12: Ok
... A230: FR7064446 | B230: ok

Sheet Sheet8
A1: No. | B1: Forecast? | C1: Ticket | D1: Node | E1: Name | F1: Parent | G1: Action | H1: STATUS | I1: STATUS Check | J1: Sector | K1: Comments | L1: SANITY | M1: Author
A2: 3727 | B2: F1 | C2: FR7010885 | D2: G000000919 | E2: SM-PTT IVV Allocation CCs | G2: Rename | J2: MGF | K2: WTF, duplicated | L2: not done | M2: Marcus Morowski

Sheet Pvt
A1: STATUS | H1: Please wait for the GCOH structure preview, but based on our record, everything has been accounted for already.
A3: Row Labels | B3: Count of No. | C3: sd
A4: FR6934915 | B4: 3 | C4: ok
A5: Completed | B5: 3
A6: FR6952137 | B6: 2 | C6: ok
A7: Completed | B7: 2
A8: FR6995596 | B8: 7 | C8: ok
A9: Completed | B9: 7
A10: FR7010885 | B10: 7 | C10: ok
A11: Completed | B11: 6
A12: Not to work on | B12: 1
A13: FR7015139 | B13: 3 | C13: ok
A14: Completed | B14: 3
A15: FR7037412 | B15: 42 | C15: ok
A16: Completed | B16: 42
A17: FR7040358 | B17: 1 | C17: ok
A18: Completed | B18: 1
A19: FR7040888 | B19: 110 | C19: ok
A20: Completed | B20: 110
A21: FR7047478 | B21: 7 | C21: ok
A22: Completed | B22: 7
A23: FR7049853 | B23: 7 | C23: ok
A24: Completed | B24: 7
A25: FR7052523 | B25: 13 | C25: ok
A26: Completed | B26: 13
A27: FR7052768 | B27: 3 | C27: ok
A28: Completed | B28: 3
A29: FR7060566 | B29: 2 | C29: ok
A30: Completed | B30: 2
A31: FR7064446 | B31: 1 | C31: ok
A32: Completed | B32: 1
A33: Grand Total | B33: 208

Sheet KPI
A2: STATUS | B2: (All)
A4: Count of No. | B4: Column Labels
B5: F0 | G5: F0 Total | H5: F1 | M5: F1 Total | N5: F2 | S5: F2 Total | T5: F3 | Y5: F3 Total | Z5: Grand Total
A6: Row Labels | B6: Delete | C6: Move | D6: New | E6: Rename | F6: Rename/Move | H6: Delete | I6: Move | J6: New | K6: Rename | L6: Rename/Move | N6: Delete | O6: Move | P6: New | Q6: Rename | R6: Rename/Move | T6: Delete | U6: Move | V6: New | W6: Rename | X6: Rename/Move
A7: MGF | B7: 50 | C7: 48 | D7: 192 | E7: 273 | F7: 116 | G7: 679 | H7: 5 | I7: 43 | J7: 20 | K7: 65 | L7: 7 | M7: 140 | O7: 23 | P7: 29 | Q7: 46 | R7: 4 | S7: 102 | U7: 15 | V7: 23 | W7: 54 | X7: 1 | Y7: 93 | Z7: 1014
A8: LS | B8: 9 | C8: 374 | D8: 95 | E8: 164 | F8: 18 | G8: 660 | H8: 2 | I8: 77 | J8: 30 | K8: 96 | L8: 22 | M8: 227 | O8: 403 | P8: 81 | Q8: 82 | S8: 566 | U8: 245 | V8: 20 | W8: 68 | X8: 4 | Y8: 337 | Z8: 1790
A9: HC | B9: 5 | C9: 1 | D9: 21 | E9: 14 | F9: 8 | G9: 49 | H9: 1 | I9: 1 | J9: 5 | K9: 12 | M9: 19 | N9: 14 | O9: 8 | P9: 5 | Q9: 8 | R9: 1 | S9: 36 | T9: 7 | U9: 11 | V9: 3 | W9: 3 | Y9: 24 | Z9: 128
A10: EL | B10: 14 | D10: 105 | E10: 158 | F10: 22 | G10: 299 | H10: 20 | I10: 4 | J10: 26 | K10: 529 | L10: 4 | M10: 583 | O10: 4 | P10: 15 | Q10: 1 | S10: 20 | U10: 67 | V10: 13 | W10: 3 | X10: 1 | Y10: 84 | Z10: 986
A11: Grand Total | B11: 78 | C11: 423 | D11: 413 | E11: 609 | F11: 164 | G11: 1687 | H11: 28 | I11: 125 | J11: 81 | K11: 702 | L11: 33 | M11: 969 | N11: 14 | O11: 438 | P11: 130 | Q11: 137 | R11: 5 | S11: 724 | T11: 7 | U11: 338 | V11: 59 | W11: 128 | X11: 6 | Y11: 538 | Z11: 3918
