Workbook

Sheet pvt
A1: STATUS
A3: Row Labels | B3: Count of Node
A4: FR8342498 | B4: 3
A5: ON TM1 | B5: 3
A6: FR8345021 | B6: 2
A7: ON TM1 | B7: 2
A8: FR8348206 | B8: 3
A9: ON TM1 | B9: 3
A10: Grand Total | B10: 8

Sheet Okey
A1: FR5208660 | B1: Ok
A2: FR5265964 | B2: Ok
A3: FR5266249 | B3: Ok
A4: FR5267957 | B4: Ok
A5: FR5267969 | B5: Ok
A6: FR5286834 | B6: Ok
A7: FR5068879 | B7: Ok
A8: FR5072548 | B8: Ok
A9: FR5082089 | B9: Ok
A10: FR5092977 | B10: Ok
A11: FR5099062 | B11: Ok
A12: FR5107986 | B12: Ok
... A350: FR8348206 | B350: ok

Sheet STUCT1
A1: No. | B1: Forecast? | C1: Ticket | D1: Node | E1: Name | F1: Parent | G1: Action | H1: STATUS | I1: STATUS Check | J1: Sector | K1: Comments | L1: SANITY | M1: Author
A2: 1 | B2: F1 | C2: FR8003901 | D2: IT08030000 | E2: MGF_(non-IT) | F2: G000000244 | G2: New | H2: =IFERROR(VLOOKUP(Table2[[#This Row], [Ticket]],Okey!A:B,2,0),"") -> ok | I2: ON TM1 | J2: MGF | M2: Joshua Cachola
A3: =1+A2 -> 2 | B3: F1 | C3: FR8003901 | D3: G000000850 | F3: G000000400 | G3: Move | H3: =IFERROR(VLOOKUP(Table2[[#This Row], [Ticket]],Okey!A:B,2,0),"") -> ok | I3: ON TM1 | J3: MGF | M3: Manuel Walther
A4: =1+A3 -> 3 | B4: F1 | C4: FR8003901 | D4: G000000927 | E4: NO USE | F4: G000000873 | G4: Rename/Move | H4: =IFERROR(VLOOKUP(Table2[[#This Row], [Ticket]],Okey!A:B,2,0),"") -> ok | I4: ON TM1 | J4: MGF | M4: Manuel Walther
A5: =1+A4 -> 4 | B5: F1 | C5: FR8003901 | D5: G000000928 | E5: NO USE | F5: G000000873 | G5: Rename/Move | H5: =IFERROR(VLOOKUP(Table2[[#This Row], [Ticket]],Okey!A:B,2,0),"") -> ok | I5: ON TM1 | J5: MGF | M5: Manuel Walther
A6: =1+A5 -> 5 | B6: F1 | C6: FR8003901 | D6: G000000849 | E6: NO USE | F6: G000000873 | G6: Rename/Move | H6: =IFERROR(VLOOKUP(Table2[[#This Row], [Ticket]],Okey!A:B,2,0),"") -> ok | I6: ON TM1 | J6: MGF | M6: Manuel Walther
A7: =1+A6 -> 6 | B7: F1 | C7: FR8003901 | D7: G000000851 | E7: NO USE | F7: G000000873 | G7: Rename/Move | H7: =IFERROR(VLOOKUP(Table2[[#This Row], [Ticket]],Okey!A:B,2,0),"") -> ok | I7: ON TM1 | J7: MGF | M7: Manuel Walther
A8: =1+A7 -> 7 | B8: F1 | C8: FR8003901 | D8: G000000847 | E8: SM-G Mirror CC Typ-C Equipment | G8: Rename | H8: =IFERROR(VLOOKUP(Table2[[#This Row], [Ticket]],Okey!A:B,2,0),"") -> ok | I8: ON TM1 | J8: MGF | M8: Manuel Walther
A9: =1+A8 -> 8 | B9: F1 | C9: FR8003901 | D9: G000000848 | E9: SM-G Mirror CC Typ-R Reimburs. (h alloc) | G9: Rename | H9: =IFERROR(VLOOKUP(Table2[[#This Row], [Ticket]],Okey!A:B,2,0),"") -> ok | I9: ON TM1 | J9: MGF | M9: Manuel Walther
A10: =1+A9 -> 9 | B10: F1 | C10: FR8003901 | D10: G000000929 | E10: NO USE | G10: Rename | H10: =IFERROR(VLOOKUP(Table2[[#This Row], [Ticket]],Okey!A:B,2,0),"") -> ok | I10: ON TM1 | J10: MGF | M10: Manuel Walther
A11: =1+A10 -> 10 | B11: F1 | C11: FR8003901 | D11: G000000930 | E11: NO USE | G11: Rename | H11: =IFERROR(VLOOKUP(Table2[[#This Row], [Ticket]],Okey!A:B,2,0),"") -> ok | I11: ON TM1 | J11: MGF | M11: Manuel Walther
A12: =1+A11 -> 11 | B12: F1 | C12: FR8003901 | D12: G000000931 | E12: NO USE | G12: Rename | H12: =IFERROR(VLOOKUP(Table2[[#This Row], [Ticket]],Okey!A:B,2,0),"") -> ok | I12: ON TM1 | J12: MGF | M12: Manuel Walther
A13: =1+A12 -> 12 | B13: F1 | C13: FR8003901 | D13: G000000926 | E13: NO USE | G13: Rename | H13: =IFERROR(VLOOKUP(Table2[[#This Row], [Ticket]],Okey!A:B,2,0),"") -> ok | I13: ON TM1 | J13: MGF | M13: Manuel Walther
A14: =1+A13 -> 13 | B14: F1 | C14: FR8003901 | D14: G000000852 | E14: NO USE | G14: Rename | H14: =IFERROR(VLOOKUP(Table2[[#This Row], [Ticket]],Okey!A:B,2,0),"") -> ok | I14: ON TM1 | J14: MGF | M14: Manuel Walther
A15: =1+A14 -> 14 | B15: F1 | C15: FR8003901 | D15: G000000935 | E15: NO USE | G15: Rename | H15: =IFERROR(VLOOKUP(Table2[[#This Row], [Ticket]],Okey!A:B,2,0),"") -> ok | I15: ON TM1 | J15: MGF | M15: Manuel Walther
A16: =1+A15 -> 15 | B16: F1 | C16: FR8003901 | D16: G000000936 | E16: NO USE | G16: Rename | H16: =IFERROR(VLOOKUP(Table2[[#This Row], [Ticket]],Okey!A:B,2,0),"") -> ok | I16: ON TM1 | J16: MGF | M16: Manuel Walther
A17: =1+A16 -> 16 | B17: F1 | C17: FR8003901 | D17: G000000937 | E17: NO USE | G17: Rename | H17: =IFERROR(VLOOKUP(Table2[[#This Row], [Ticket]],Okey!A:B,2,0),"") -> ok | I17: ON TM1 | J17: MGF | M17: Manuel Walther
A18: =1+A17 -> 17 | B18: F1 | C18: FR8003901 | D18: G000000938 | E18: NO USE | G18: Rename | H18: =IFERROR(VLOOKUP(Table2[[#This Row], [Ticket]],Okey!A:B,2,0),"") -> ok | I18: ON TM1 | J18: MGF | M18: Manuel Walther
A19: =1+A18 -> 18 | B19: F1 | C19: FR8003901 | D19: G000000939 | E19: NO USE | G19: Rename | H19: =IFERROR(VLOOKUP(Table2[[#This Row], [Ticket]],Okey!A:B,2,0),"") -> ok | I19: ON TM1 | J19: MGF | M19: Manuel Walther
A20: =1+A19 -> 19 | B20: F1 | C20: FR8003901 | D20: G000000940 | E20: NO USE | G20: Rename | H20: =IFERROR(VLOOKUP(Table2[[#This Row], [Ticket]],Okey!A:B,2,0),"") -> ok | I20: ON TM1 | J20: MGF | M20: Manuel Walther
A21: =1+A20 -> 20 | B21: F1 | C21: FR8026550 | D21: RDC0000095 | F21: H000004396 | G21: Move | H21: =IFERROR(VLOOKUP(Table2[[#This Row], [Ticket]],Okey!A:B,2,0),"") -> ok | I21: ON TM1 | J21: MGF | M21: Erjo Miguel Tagle
A22: =1+A21 -> 21 | B22: F1 | C22: FR8025258 | D22: H000004863 | E22: SCALA_1248 A350 | F22: H000000726 | G22: New | H22: =IFERROR(VLOOKUP(Table2[[#This Row], [Ticket]],Okey!A:B,2,0),"") -> ok | I22: ON TM1 | J22: MGF | M22: Erjo Miguel Tagle
A23: =1+A22 -> 22 | B23: F1 | C23: FR8025258 | D23: H000004864 | E23: SCALA_1248 A351 | F23: H000000802 | G23: New | H23: =IFERROR(VLOOKUP(Table2[[#This Row], [Ticket]],Okey!A:B,2,0),"") -> ok | I23: ON TM1 | J23: MGF | M23: Erjo Miguel Tagle
A24: =1+A23 -> 23 | B24: F1 | C24: FR8025258 | D24: H000004865 | E24: SCALA_1248 A353 | F24: H000000802 | G24: New | H24: =IFERROR(VLOOKUP(Table2[[#This Row], [Ticket]],Okey!A:B,2,0),"") -> ok | I24: ON TM1 | J24: MGF | M24: Erjo Miguel Tagle
A25: =1+A24 -> 24 | B25: F1 | C25: FR8025258 | D25: RDC0000095 | F25: H000004396 | G25: Move | H25: =IFERROR(VLOOKUP(Table2[[#This Row], [Ticket]],Okey!A:B,2,0),"") -> ok | I25: ON TM1 | J25: MGF | M25: Erjo Miguel Tagle
A26: =1+A25 -> 25 | B26: F1 | C26: FR8068790 | D26: H000004866 | E26: MERCK SERONO ITALY - BARI (CCH) | F26: H000000471 | G26: New | H26: =IFERROR(VLOOKUP(Table2[[#This Row], [Ticket]],Okey!A:B,2,0),"") -> ok | I26: ON TM1 | J26: HC | M26: Murilo Barbosa
A27: =1+A26 -> 26 | B27: F1 | C27: FR8068790 | D27: H000004867 | E27: 1250BA - OPERATIONS | F27: H000004866 | G27: New | H27: =IFERROR(VLOOKUP(Table2[[#This Row], [Ticket]],Okey!A:B,2,0),"") -> ok | I27: ON TM1 | J27: HC | M27: Murilo Barbosa
A28: =1+A27 -> 27 | B28: F1 | C28: FR8068790 | D28: H000004868 | E28: 1250BA - OPERATIONS SUPPORT SERVICES | F28: H000004866 | G28: New | H28: =IFERROR(VLOOKUP(Table2[[#This Row], [Ticket]],Okey!A:B,2,0),"") -> ok | I28: ON TM1 | J28: HC | M28: Murilo Barbosa
A29: =1+A28 -> 28 | B29: F1 | C29: FR8068790 | D29: H000004869 | E29: 1250BA - SITE INFRASTRUCTURE | F29: H000004866 | G29: New | H29: =IFERROR(VLOOKUP(Table2[[#This Row], [Ticket]],Okey!A:B,2,0),"") -> ok | I29: ON TM1 | J29: HC | M29: Murilo Barbosa
A30: =1+A29 -> 29 | B30: F1 | C30: FR8068790 | D30: H000004870 | E30: 1250BA - QUALITY | F30: H000004866 | G30: New | H30: =IFERROR(VLOOKUP(Table2[[#This Row], [Ticket]],Okey!A:B,2,0),"") -> ok | I30: ON TM1 | J30: HC | M30: Murilo Barbosa
A31: =1+A30 -> 30 | B31: F1 | C31: FR8068790 | D31: H000004871 | E31: 1250BA - OTHERS | F31: H000004866 | G31: New | H31: =IFERROR(VLOOKUP(Table2[[#This Row], [Ticket]],Okey!A:B,2,0),"") -> ok | I31: ON TM1 | J31: HC | M31: Murilo Barbosa
A32: =1+A31 -> 31 | B32: F1 | C32: FR8068790 | D32: H000004872 | E32: 1250BA - MANUFACTURING | F32: H000004867 | G32: New | H32: =IFERROR(VLOOKUP(Table2[[#This Row], [Ticket]],Okey!A:B,2,0),"") -> ok | I32: ON TM1 | J32: HC | M32: Murilo Barbosa
A33: =1+A32 -> 32 | B33: F1 | C33: FR8068790 | D33: H000004873 | E33: 1250BA - PACKAGING | F33: H000004867 | G33: New | H33: =IFERROR(VLOOKUP(Table2[[#This Row], [Ticket]],Okey!A:B,2,0),"") -> ok | I33: ON TM1 | J33: HC | M33: Murilo Barbosa
A34: =1+A33 -> 33 | B34: F1 | C34: FR8068790 | D34: H000004874 | E34: 1250BA - MAINTENANCE AND ENGINEERING | F34: H000004868 | G34: New | H34: =IFERROR(VLOOKUP(Table2[[#This Row], [Ticket]],Okey!A:B,2,0),"") -> ok | I34: ON TM1 | J34: HC | M34: Murilo Barbosa
A35: =1+A34 -> 34 | B35: F1 | C35: FR8068790 | D35: H000004875 | E35: 1250BA - SUPPLY AND PLANNING | F35: H000004868 | G35: New | H35: =IFERROR(VLOOKUP(Table2[[#This Row], [Ticket]],Okey!A:B,2,0),"") -> ok | I35: ON TM1 | J35: HC | M35: Murilo Barbosa
A36: =1+A35 -> 35 | B36: F1 | C36: FR8068790 | D36: H000004876 | E36: 1250BA - SITE SERVICES | F36: H000004868 | G36: New | H36: =IFERROR(VLOOKUP(Table2[[#This Row], [Ticket]],Okey!A:B,2,0),"") -> ok | I36: ON TM1 | J36: HC | M36: Murilo Barbosa
A37: =1+A36 -> 36 | B37: F1 | C37: FR8068790 | D37: H000004877 | E37: 1250BA - MANUFACTURING FACILITIES | F37: H000004869 | G37: New | H37: =IFERROR(VLOOKUP(Table2[[#This Row], [Ticket]],Okey!A:B,2,0),"") -> ok | I37: ON TM1 | J37: HC | M37: Murilo Barbosa
... A53: =1+A52 -> 52 | B53: F1 | C53: FR8078176 | D53: IT06042600 | E53: EF-DS-TIX Special Projects | F53: G000001461 | G53: New | H53: =IFERROR(VLOOKUP(Table2[[#This Row], [Ticket]],Okey!A:B,2,0),"") -> ok | I53: ON TM1 | J53: MGF | M53: Jay-R Lizardo
A54: =1+A53 -> 53 | B54: F1 | C54: FR8089834 | D54: G000000416 | E54: SM-RG Restaurants & Catering | G54: Rename | H54: =IFERROR(VLOOKUP(Table2[[#This Row], [Ticket]],Okey!A:B,2,0),"") -> ok | I54: ON TM1 | J54: HC
A55: =1+A54 -> 54 | B55: F1 | C55: FR8089834 | D55: G000000882 | E55: SM-RG Catering & Ursprung | G55: Rename | H55: =IFERROR(VLOOKUP(Table2[[#This Row], [Ticket]],Okey!A:B,2,0),"") -> ok | I55: ON TM1 | J55: HC
...

Sheet Sheet3
A1: 1000
A2: RDC0000142 | B2: Oligo Therapeutics | C2: X | D2: X | E2: X | F2: X | G2: X
A3: H000005088 | B3: Focus30 Global R&D | C3: X | D3: X | E3: X | F3: X | G3: X
A4: H000005089 | B4: Focus30 Local R&D | C4: X | D4: X | E4: X | F4: X | G4: X
A5: H000005018 | B5: 510.00 TEAD-No Program | C5: X | D5: X | E5: X | F5: X | G5: X
A6: H000005021 | B6: 550.00 VRK1 |No Program | C6: X | D6: X | E6: X | F6: X | G6: X
A10: 1000 | B10: Standard
A11: RDC0000130 | B11: RDC0000142
A12: H000000965 | B12: H000005088
A13: H000000965 | B13: H000005089
A14: G000000873 | B14: G000000889
A15: G000000873 | B15: G000001018
A16: H000004934 | B16: H000005016

Sheet Sheet2
A1: H000004992 | B1: H000004991
A2: H000004993 | B2: H000004991
A3: H000004994 | B3: H000004991
A4: H000005066 | B4: H000005048
A5: H000005067 | B5: H000005048
A6: H000005068 | B6: H000005048
A7: H000005069 | B7: H000005048
A8: H000005070 | B8: H000005048
A9: H000005071 | B9: H000005048
A10: H000005072 | B10: H000005048
A11: H000005073 | B11: H000005048
A12: H000005074 | B12: H000005048
... A27: L000009814 | B27: L000009795
A28: RDC0000142

Sheet Sheet1
A1: H000005066 | B1: US - Rare - Opinion Leader Laison | C1: H00000 | D1: 5066 | E1: =+C1&D1 -> H000005066 | M1: 1000 | V1: 1000
A2: H000005067 | B2: US - Rare GSI - Market Insights & Frcst | C2: H00000 | D2: =+D1+1 -> 5067 | E2: =+C2&D2 -> H000005067 | M2: H000005066 | N2: US - Rare - Opinion Leader Laison | O2: X | P2: X | Q2: X | R2: X | S2: X | V2: H000005048 | W2: H000005066
A3: H000005068 | B3: US - Rare OE&I - Cap. Bldg Eng. & Events | C3: H00000 | D3: =+D2+1 -> 5068 | E3: =+C3&D3 -> H000005068 | M3: H000005067 | N3: US - Rare GSI - Market Insights & Frcst | O3: X | P3: X | Q3: X | R3: X | S3: X | V3: H000005048 | W3: H000005067
A4: H000005069 | B4: US - Rare Diseases - GPA - Advocacy | C4: H00000 | D4: =+D3+1 -> 5069 | E4: =+C4&D4 -> H000005069 | M4: H000005068 | N4: US - Rare OE&I - Cap. Bldg Eng. & Events | O4: X | P4: X | Q4: X | R4: X | S4: X | V4: H000005048 | W4: H000005068
A5: H000005070 | B5: US - Rare Diseases - GPA - Govt Affairs | C5: H00000 | D5: =+D4+1 -> 5070 | E5: =+C5&D5 -> H000005070 | M5: H000005069 | N5: US - Rare Diseases - GPA - Advocacy | O5: X | P5: X | Q5: X | R5: X | S5: X | V5: H000005048 | W5: H000005069
A6: H000005071 | B6: US - Rare GPA - Innovative Med Policy | C6: H00000 | D6: =+D5+1 -> 5071 | E6: =+C6&D6 -> H000005071 | M6: H000005070 | N6: US - Rare Diseases - GPA - Govt Affairs | O6: X | P6: X | Q6: X | R6: X | S6: X | V6: H000005048 | W6: H000005070
A7: H000005072 | B7: US - Rare Diseases - Communications | C7: H00000 | D7: =+D6+1 -> 5072 | E7: =+C7&D7 -> H000005072 | M7: H000005071 | N7: US - Rare GPA - Innovative Med Policy | O7: X | P7: X | Q7: X | R7: X | S7: X | V7: H000005048 | W7: H000005071
A8: H000005073 | B8: US - Rare Diseases - New Product | C8: H00000 | D8: =+D7+1 -> 5073 | E8: =+C8&D8 -> H000005073 | M8: H000005072 | N8: US - Rare Diseases - Communications | O8: X | P8: X | Q8: X | R8: X | S8: X | V8: H000005048 | W8: H000005072
A9: H000005074 | B9: US - Rare Diseases - Hedge | C9: H00000 | D9: =+D8+1 -> 5074 | E9: =+C9&D9 -> H000005074 | M9: H000005073 | N9: US - Rare Diseases - New Product | O9: X | P9: X | Q9: X | R9: X | S9: X | V9: H000005048 | W9: H000005073
A10: H000005075 | B10: US - Rare Diseases - OE&I - Comm Ops | C10: H00000 | D10: =+D9+1 -> 5075 | E10: =+C10&D10 -> H000005075 | M10: H000005074 | N10: US - Rare Diseases - Hedge | O10: X | P10: X | Q10: X | R10: X | S10: X | V10: H000005048 | W10: H000005074
A11: H000005076 | B11: US - Rare Diseases - MAPS Value&Access | C11: H00000 | D11: =+D10+1 -> 5076 | E11: =+C11&D11 -> H000005076 | M11: H000005075 | N11: US - Rare Diseases - OE&I - Comm Ops | O11: X | P11: X | Q11: X | R11: X | S11: X | V11: H000005048 | W11: H000005075
A12: H000005077 | B12: US - Rare - MAPS Field Patient Svcs | C12: H00000 | D12: =+D11+1 -> 5077 | E12: =+C12&D12 -> H000005077 | M12: H000005076 | N12: US - Rare Diseases - MAPS Value&Access | O12: X | P12: X | Q12: X | R12: X | S12: X | V12: H000005048 | W12: H000005076
A13: H000005078 | B13: US - Rare Diseases - Medical Education | C13: H00000 | D13: =+D12+1 -> 5078 | E13: =+C13&D13 -> H000005078 | M13: H000005077 | N13: US - Rare - MAPS Field Patient Svcs | O13: X | P13: X | Q13: X | R13: X | S13: X | V13: H000005048 | W13: H000005077
... A22: H000005087 | B22: US - Rare Diseases - Samples | C22: H00000 | D22: =+D21+1 -> 5087 | E22: =+C22&D22 -> H000005087 | M22: H000005086 | N22: US - Rare Diseases - Studies | O22: X | P22: X | Q22: X | R22: X | S22: X | V22: H000005059 | W22: H000005086
M23: H000005087 | N23: US - Rare Diseases - Samples | O23: X | P23: X | Q23: X | R23: X | S23: X | V23: H000005059 | W23: H000005087
M24: H000005055 | N24: US - Rare Diseases - OE&I Data Strat | O24: X | P24: X | Q24: X | R24: X | S24: X
M25: L000009814 | N25: Cranbury 3PL WH -G | O25: X | P25: X | Q25: X | R25: X | S25: X

Sheet Names
A1: 1000
A2: G000000951 | B2: SC Gebaeude Electronics DA | C2: X | D2: X | E2: X | F2: X | G2: X
A3: G000000531 | B3: Freiflaechen und allg. Infrastruktur | C3: X | D3: X | E3: X | F3: X | G3: X
A4: G000000532 | B4: Freiflaechen und Parken | C4: X | D4: X | E4: X | F4: X | G4: X
A5: G000000945 | B5: Allgemeine Infrastruktur | C5: X | D5: X | E5: X | F5: X | G5: X
A6: G000000089 | B6: SM-IE Energy Operations & Management | C6: X | D6: X | E6: X | F6: X | G6: X
A7: G000000472 | B7: SM-HI Ideenmanagement | C7: X | D7: X | E7: X | F7: X | G7: X
A8: L000013826 | B8: LW - Ecommerce Specialist | C8: X | D8: X | E8: X | F8: X | G8: X
A9: L000013827 | B9: LW - Global Digital Camp | C9: X | D9: X | E9: X | F9: X | G9: X
A10: L000013828 | B10: LW - Content Manager | C10: X | D10: X | E10: X | F10: X | G10: X
A11: L000013829 | B11: LW - Mark&Digit Comm Spe | C11: X | D11: X | E11: X | F11: X | G11: X
A12: L000013830 | B12: Schnelldorf DF Operations CCV | C12: X | D12: X | E12: X | F12: X | G12: X
A13: L000013831 | B13: LS ERP Travel | C13: X | D13: X | E13: X | F13: X | G13: X
... A235: H000004395 | B235: IF-China & International exc GH | C235: X | D235: X | E235: X | F235: X | G235: X
A237: KR00
A238: G000000951 | B238: SC Gebaeude Electronics DA | C238: X
A239: G000000531 | B239: Freiflaechen und allg. Infrastruktur | C239: X
A240: G000000532 | B240: Freiflaechen und Parken | C240: X
A241: G000000945 | B241: Allgemeine Infrastruktur | C241: X
A242: G000000089 | B242: SM-IE Energy Operations & Management | C242: X
A243: G000000472 | B243: SM-HI Ideenmanagement | C243: X
A244: G000001265 | B244: GMR MBS Innovation & Data-Int.Automation | C244: X
A245: G000001211 | B245: GLW MBS FS&P PO-Perform.Mgmt &Compl. PO | C245: X
A246: G000001219 | B246: GMG MBS FS&P Ent.S.-Communication Serv. | C246: X
A247: G000000006 | B247: F79 CO - Group Controlling | C247: X
A248: G000000008 | B248: GK3 CO - Group Controlling (L2) | C248: X
A249: G000001287 | B249: GYG MBS Hub Bangalore - SLS Buss Operati | C249: X
... A388: P000000533 | B388: EL-TF Thin Film Commercial | C388: X

Sheet NEW NODES
A1: 1000 | D1: KR00
A2: L000013126 | B2: L000013826 | D2: G000000613 | E2: G000001359
A3: L000013126 | B3: L000013827 | D3: G000000622 | E3: G000001360
A4: L000013126 | B4: L000013828 | D4: G000000622 | E4: G000001361
A5: L000013126 | B5: L000013829 | D5: G000000622 | E5: G000001362
A6: L000012340 | B6: L000013830 | D6: G000000622 | E6: G000001363
A7: L000013799 | B7: L000013831 | D7: G000000622 | E7: G000001364
A8: L000009975 | B8: L000013832 | D8: G000000622 | E8: G000001365
A9: L000013451 | B9: L000013833 | D9: G000000622 | E9: G000001366
A10: L000013833 | B10: L000013834 | D10: G000000184 | E10: G000001367
A11: L000013833 | B11: L000013835 | D11: G000001367 | E11: G000001368
A12: L000013779 | B12: L000013836 | D12: G000001367 | E12: G000001369
A13: L000013854 | B13: L000013837 | D13: G000001368 | E13: G000001370
... A74: P000000554 | B74: P000001275 | D74: P000000748 | E74: P000001324
A75: P000000554 | B75: P000001276
A76: P000000554 | B76: P000001277
A77: P000001275 | B77: P000001278
A78: P000001275 | B78: P000001279
A79: P000001275 | B79: P000001280
A80: P000001275 | B80: P000001281
A81: P000001275 | B81: P000001282
A82: P000001276 | B82: P000001283
A83: P000001276 | B83: P000001284
A84: P000001276 | B84: P000001285
A85: P000001276 | B85: P000001286
A86: P000001276 | B86: P000001287
... A125: H000000172 | B125: H000004395

Sheet People
A1: Opened By | B1: Sector
A2: Joshua Cachola | B2: MGF
A3: Simone Oratovski | B3: HC
A4: Nicolas Trautmann | B4: MGF
A5: Henry Ifurung Jr. | B5: HC
A6: Phoebe Anne Fortaleza | B6: LS
A7: Joebeth Navarro | B7: HC
A8: Paul Kopp | B8: MGF
A9: Maureen Cardano | B9: HC
A10: Roland Earvin Combalicer | B10: HC
A11: Marcus Morowski | B11: MGF
A12: Megan Wang | B12: MGF
... A55: Hui Zhang | B55: LS

Sheet 2023
A1: No. | B1: Forecast? | C1: Ticket | D1: Node | E1: Name | F1: Parent | G1: Action | H1: STATUS | I1: STATUS Check | J1: Sector | K1: Comments | L1: SANITY | M1: Author
A2: 1 | B2: F1 | C2: FR5068879 | D2: L000011515 | F2: O000000009 | G2: Delete | H2: =IFERROR(VLOOKUP(Table2[[#This Row], [Ticket]],Okey!A:B,2,0),"") -> ok | I2: Closed | J2: =VLOOKUP(Table2[[#This Row], [Author]],People!A:B,2,0) -> MGF | M2: Phoebe Anne Fortaleza
A3: =1+A2 -> 2 | B3: F1 | C3: FR5068879 | D3: L000013398 | E3: BioVV - Quality & Regulatory -G | F3: L000006935 | G3: New | H3: =IFERROR(VLOOKUP(Table2[[#This Row], [Ticket]],Okey!A:B,2,0),"") -> ok | I3: Closed | J3: =VLOOKUP(Table2[[#This Row], [Author]],People!A:B,2,0) -> MGF | M3: Phoebe Anne Fortaleza
A4: =1+A3 -> 3 | B4: F1 | C4: FR5072548 | D4: G000000958 | F4: G000000955 | G4: Move | H4: =IFERROR(VLOOKUP(Table2[[#This Row], [Ticket]],Okey!A:B,2,0),"") -> ok | I4: Closed | J4: =VLOOKUP(Table2[[#This Row], [Author]],People!A:B,2,0) -> MGF | M4: Nadine Anic
A5: =1+A4 -> 4 | B5: F1 | C5: FR5072548 | D5: G000000959 | F5: G000000958 | G5: Move | H5: =IFERROR(VLOOKUP(Table2[[#This Row], [Ticket]],Okey!A:B,2,0),"") -> ok | I5: Closed | J5: =VLOOKUP(Table2[[#This Row], [Author]],People!A:B,2,0) -> MGF | M5: Nadine Anic
A6: =1+A5 -> 5 | B6: F1 | C6: FR5072548 | D6: G000000960 | F6: G000000958 | G6: Move | H6: =IFERROR(VLOOKUP(Table2[[#This Row], [Ticket]],Okey!A:B,2,0),"") -> ok | I6: Closed | J6: =VLOOKUP(Table2[[#This Row], [Author]],People!A:B,2,0) -> MGF | M6: Nadine Anic
A7: =1+A6 -> 6 | B7: F1 | C7: FR5072548 | D7: G000000961 | F7: G000000958 | G7: Move | H7: =IFERROR(VLOOKUP(Table2[[#This Row], [Ticket]],Okey!A:B,2,0),"") -> ok | I7: Closed | J7: =VLOOKUP(Table2[[#This Row], [Author]],People!A:B,2,0) -> MGF | M7: Nadine Anic
A8: =1+A7 -> 7 | B8: F1 | C8: FR5072548 | D8: G000000962 | F8: G000000958 | G8: Move | H8: =IFERROR(VLOOKUP(Table2[[#This Row], [Ticket]],Okey!A:B,2,0),"") -> ok | I8: Closed | J8: =VLOOKUP(Table2[[#This Row], [Author]],People!A:B,2,0) -> MGF | M8: Nadine Anic
A9: =1+A8 -> 8 | B9: F1 | C9: FR5072548 | D9: G000000963 | F9: G000000958 | G9: Move | H9: =IFERROR(VLOOKUP(Table2[[#This Row], [Ticket]],Okey!A:B,2,0),"") -> ok | I9: Closed | J9: =VLOOKUP(Table2[[#This Row], [Author]],People!A:B,2,0) -> MGF | M9: Nadine Anic
A10: =1+A9 -> 9 | B10: F1 | C10: FR5072548 | D10: G000000964 | F10: G000000958 | G10: Move | H10: =IFERROR(VLOOKUP(Table2[[#This Row], [Ticket]],Okey!A:B,2,0),"") -> ok | I10: Closed | J10: =VLOOKUP(Table2[[#This Row], [Author]],People!A:B,2,0) -> MGF | M10: Nadine Anic
A11: =1+A10 -> 10 | B11: F1 | C11: FR5072548 | D11: G000000965 | F11: G000000958 | G11: Move | H11: =IFERROR(VLOOKUP(Table2[[#This Row], [Ticket]],Okey!A:B,2,0),"") -> ok | I11: Closed | J11: =VLOOKUP(Table2[[#This Row], [Author]],People!A:B,2,0) -> MGF | M11: Nadine Anic
A12: =1+A11 -> 11 | B12: F1 | C12: FR5072548 | D12: G000000966 | F12: G000000955 | G12: Move | H12: =IFERROR(VLOOKUP(Table2[[#This Row], [Ticket]],Okey!A:B,2,0),"") -> ok | I12: Closed | J12: =VLOOKUP(Table2[[#This Row], [Author]],People!A:B,2,0) -> MGF | M12: Nadine Anic
A13: =1+A12 -> 12 | B13: F1 | C13: FR5072548 | D13: G000000967 | F13: G000000956 | G13: Move | H13: =IFERROR(VLOOKUP(Table2[[#This Row], [Ticket]],Okey!A:B,2,0),"") -> ok | I13: Closed | J13: =VLOOKUP(Table2[[#This Row], [Author]],People!A:B,2,0) -> MGF | M13: Nadine Anic
A14: =1+A13 -> 13 | B14: F1 | C14: FR5072548 | D14: G000000968 | F14: G000000967 | G14: Move | H14: =IFERROR(VLOOKUP(Table2[[#This Row], [Ticket]],Okey!A:B,2,0),"") -> ok | I14: Closed | J14: =VLOOKUP(Table2[[#This Row], [Author]],People!A:B,2,0) -> MGF | M14: Nadine Anic
A15: =1+A14 -> 14 | B15: F1 | C15: FR5072548 | D15: G000000969 | F15: G000000967 | G15: Move | H15: =IFERROR(VLOOKUP(Table2[[#This Row], [Ticket]],Okey!A:B,2,0),"") -> ok | I15: Closed | J15: =VLOOKUP(Table2[[#This Row], [Author]],People!A:B,2,0) -> MGF | M15: Nadine Anic
... A41: =1+A40 -> 40 | B41: F1 | C41: FR5072548 | D41: G000000995 | F41: G000000993 | G41: Move | H41: =IFERROR(VLOOKUP(Table2[[#This Row], [Ticket]],Okey!A:B,2,0),"") -> ok | I41: Closed | J41: =VLOOKUP(Table2[[#This Row], [Author]],People!A:B,2,0) -> #N/A | M41: Nadine Anic
A42: =1+A41 -> 41 | B42: F1 | C42: FR5082089 | D42: G000000461 | E42: SM-B Strategy Realization & Enablement | G42: Rename | H42: =IFERROR(VLOOKUP(Table2[[#This Row], [Ticket]],Okey!A:B,2,0),"") -> ok | I42: Closed | J42: =VLOOKUP(Table2[[#This Row], [Author]],People!A:B,2,0) -> #N/A | M42: Sybille Rogmans
A43: =1+A42 -> 42 | B43: F1 | C43: FR5082089 | D43: G000000462 | E43: SM-B Strategy Realization & Enablement | G43: Rename | H43: =IFERROR(VLOOKUP(Table2[[#This Row], [Ticket]],Okey!A:B,2,0),"") -> ok | I43: Closed | J43: =VLOOKUP(Table2[[#This Row], [Author]],People!A:B,2,0) -> #N/A | M43: Sybille Rogmans
A44: =1+A43 -> 43 | B44: F1 | C44: FR5082089 | D44: G000000463 | E44: SM-BB Business Excellence | G44: Rename | H44: =IFERROR(VLOOKUP(Table2[[#This Row], [Ticket]],Okey!A:B,2,0),"") -> ok | I44: Closed | J44: =VLOOKUP(Table2[[#This Row], [Author]],People!A:B,2,0) -> #N/A | M44: Sybille Rogmans
A45: =1+A44 -> 44 | B45: F1 | C45: FR5082089 | D45: G000000464 | E45: SM-BS Strategy Realization | G45: Rename | H45: =IFERROR(VLOOKUP(Table2[[#This Row], [Ticket]],Okey!A:B,2,0),"") -> ok | I45: Closed | J45: =VLOOKUP(Table2[[#This Row], [Author]],People!A:B,2,0) -> #N/A | M45: Sybille Rogmans
A46: =1+A45 -> 45 | B46: F1 | C46: FR5082089 | D46: G000000466 | E46: SM-BC Strategic Contracting | G46: Rename | H46: =IFERROR(VLOOKUP(Table2[[#This Row], [Ticket]],Okey!A:B,2,0),"") -> ok | I46: Closed | J46: =VLOOKUP(Table2[[#This Row], [Author]],People!A:B,2,0) -> #N/A | M46: Sybille Rogmans
A47: =1+A46 -> 46 | B47: F1 | C47: FR5082089 | D47: G000000470 | E47: SM-BQ dummy 6 | G47: Rename | H47: =IFERROR(VLOOKUP(Table2[[#This Row], [Ticket]],Okey!A:B,2,0),"") -> ok | I47: Closed | J47: =VLOOKUP(Table2[[#This Row], [Author]],People!A:B,2,0) -> #N/A | M47: Sybille Rogmans
A48: =1+A47 -> 47 | B48: F1 | C48: FR5082089 | D48: G000000473 | E48: SM-BD Data & Digital Enablement | G48: Rename | H48: =IFERROR(VLOOKUP(Table2[[#This Row], [Ticket]],Okey!A:B,2,0),"") -> ok | I48: Closed | J48: =VLOOKUP(Table2[[#This Row], [Author]],People!A:B,2,0) -> #N/A | M48: Sybille Rogmans
A49: =1+A48 -> 48 | B49: F1 | C49: FR5082089 | D49: G000000868 | E49: SM-BP People, Change & Comms | G49: Rename | H49: =IFERROR(VLOOKUP(Table2[[#This Row], [Ticket]],Okey!A:B,2,0),"") -> ok | I49: Closed | J49: =VLOOKUP(Table2[[#This Row], [Author]],People!A:B,2,0) -> #N/A | M49: Sybille Rogmans
A50: =1+A49 -> 49 | B50: F1 | C50: FR5082089 | D50: G000000471 | E50: SM-BQ Quality Management | F50: G000000470 | G50: Rename/Move | H50: =IFERROR(VLOOKUP(Table2[[#This Row], [Ticket]],Okey!A:B,2,0),"") -> ok | I50: Closed | J50: =VLOOKUP(Table2[[#This Row], [Author]],People!A:B,2,0) -> #N/A | M50: Sybille Rogmans
A51: =1+A50 -> 50 | B51: F1 | C51: FR5092977 | D51: G000000355 | E51: SM Site Management | G51: Rename | H51: =IFERROR(VLOOKUP(Table2[[#This Row], [Ticket]],Okey!A:B,2,0),"") -> ok | I51: Closed | J51: =VLOOKUP(Table2[[#This Row], [Author]],People!A:B,2,0) -> #N/A | M51: Nicolas Trautmann
A52: =1+A51 -> 51 | B52: F1 | C52: FR5092977 | D52: G000000359 | E52: SM-H Strategy & Transform. | G52: Rename | H52: =IFERROR(VLOOKUP(Table2[[#This Row], [Ticket]],Okey!A:B,2,0),"") -> ok | I52: Closed | J52: =VLOOKUP(Table2[[#This Row], [Author]],People!A:B,2,0) -> LS | M52: Nicolas Trautmann
A53: =1+A52 -> 52 | B53: F1 | C53: FR5092977 | D53: G000000365 | E53: SM-A Analytical Services | G53: Rename | H53: =IFERROR(VLOOKUP(Table2[[#This Row], [Ticket]],Okey!A:B,2,0),"") -> ok | I53: Closed | J53: =VLOOKUP(Table2[[#This Row], [Author]],People!A:B,2,0) -> LS | M53: Nicolas Trautmann
A54: =1+A53 -> 53 | B54: F1 | C54: FR5092977 | D54: G000000372 | E54: SM-E Engineering Services | G54: Rename | H54: =IFERROR(VLOOKUP(Table2[[#This Row], [Ticket]],Okey!A:B,2,0),"") -> ok | I54: Closed | J54: =VLOOKUP(Table2[[#This Row], [Author]],People!A:B,2,0) -> #N/A | M54: Nicolas Trautmann
A55: =1+A54 -> 54 | B55: F1 | C55: FR5092977 | D55: G000000410 | E55: SM-U | G55: Rename | H55: =IFERROR(VLOOKUP(Table2[[#This Row], [Ticket]],Okey!A:B,2,0),"") -> ok | I55: Closed | J55: =VLOOKUP(Table2[[#This Row], [Author]],People!A:B,2,0) -> #N/A | M55: Nicolas Trautmann
A56: =1+A55 -> 55 | B56: F1 | C56: FR5092977 | D56: G000000439 | E56: SM-Verrechnungen / Sachkosten | G56: Rename | H56: =IFERROR(VLOOKUP(Table2[[#This Row], [Ticket]],Okey!A:B,2,0),"") -> ok | I56: Closed | J56: =VLOOKUP(Table2[[#This Row], [Author]],People!A:B,2,0) -> #N/A | M56: Nicolas Trautmann
A57: =1+A56 -> 56 | B57: F1 | C57: FR5092977 | D57: G000000890 | E57: SM-HG Fluxum | G57: Rename | H57: =IFERROR(VLOOKUP(Table2[[#This Row], [Ticket]],Okey!A:B,2,0),"") -> ok | I57: Closed | J57: =VLOOKUP(Table2[[#This Row], [Author]],People!A:B,2,0) -> #N/A | M57: Nicolas Trautmann
A58: =1+A57 -> 57 | B58: F1 | C58: FR5092977 | D58: G000000360 | E58: SM-HF Future | G58: Rename | H58: =IFERROR(VLOOKUP(Table2[[#This Row], [Ticket]],Okey!A:B,2,0),"") -> ok | I58: Closed | J58: =VLOOKUP(Table2[[#This Row], [Author]],People!A:B,2,0) -> #N/A | M58: Nicolas Trautmann
A59: =1+A58 -> 58 | B59: F1 | C59: FR5092977 | D59: G000000361 | E59: DA Goes Global | G59: Rename | H59: =IFERROR(VLOOKUP(Table2[[#This Row], [Ticket]],Okey!A:B,2,0),"") -> ok | I59: Closed | J59: =VLOOKUP(Table2[[#This Row], [Author]],People!A:B,2,0) -> #N/A | M59: Nicolas Trautmann
A60: =1+A59 -> 59 | B60: F1 | C60: FR5092977 | D60: G000000362 | E60: SM-HM Marketing&Dialog | G60: Rename | H60: =IFERROR(VLOOKUP(Table2[[#This Row], [Ticket]],Okey!A:B,2,0),"") -> ok | I60: Closed | J60: =VLOOKUP(Table2[[#This Row], [Author]],People!A:B,2,0) -> #N/A | M60: Nicolas Trautmann
A61: =1+A60 -> 60 | B61: F1 | C61: FR5092977 | D61: G000000888 | E61: SM-HR HQ Relations & Mgmt of | G61: Rename | H61: =IFERROR(VLOOKUP(Table2[[#This Row], [Ticket]],Okey!A:B,2,0),"") -> ok | I61: Closed | J61: =VLOOKUP(Table2[[#This Row], [Author]],People!A:B,2,0) -> #N/A | M61: Nicolas Trautmann
A62: =1+A61 -> 61 | B62: F1 | C62: FR5092977 | D62: G000000889 | E62: SM-HP Plattforms | G62: Rename | H62: =IFERROR(VLOOKUP(Table2[[#This Row], [Ticket]],Okey!A:B,2,0),"") -> ok | I62: Closed | J62: =VLOOKUP(Table2[[#This Row], [Author]],People!A:B,2,0) -> #N/A | M62: Nicolas Trautmann
... A207: =1+A206 -> 206 | B207: F1 | C207: FR5092977 | D207: G000000416 | E207: SM-SCC Conference & Catering | G207: Rename | H207: =IFERROR(VLOOKUP(Table2[[#This Row], [Ticket]],Okey!A:B,2,0),"") -> ok | I207: Closed | J207: =VLOOKUP(Table2[[#This Row], [Author]],People!A:B,2,0) -> LS | M207: Nicolas Trautmann
A208: =1+A207 -> 207 | B208: F1 | C208: FR5099062 | D208: H000004191 | E208: Medical - Local R&D | F208: H000000447 | G208: New | H208: =IFERROR(VLOOKUP(Table2[[#This Row], [Ticket]],Okey!A:B,2,0),"") -> ok | I208: Closed | J208: =VLOOKUP(Table2[[#This Row], [Author]],People!A:B,2,0) -> LS | M208: Megan Wang
A209: =1+A208 -> 208 | B209: F1 | C209: FR5107986 | D209: H000000813 | E209: CMS International | G209: Rename | H209: =IFERROR(VLOOKUP(Table2[[#This Row], [Ticket]],Okey!A:B,2,0),"") -> ok | I209: Closed | J209: =VLOOKUP(Table2[[#This Row], [Author]],People!A:B,2,0) -> LS | M209: Marlon Abadia
...

Sheet 2024
A1: No. | B1: Forecast? | C1: Ticket | D1: Node | E1: Name | F1: Parent | G1: Action | H1: STATUS | I1: STATUS Check | J1: Sector | K1: Comments | L1: SANITY | M1: Author
A2: 1 | B2: F0 | C2: FR6700341 | D2: IT06042500 | F2: G000001240 | G2: Move | H2: =IFERROR(VLOOKUP(Table2[[#This Row], [Ticket]],Okey!A:B,2,0),"") -> ok | I2: completed | J2: MGF | M2: Joshua Cachola
A3: =1+A2 -> 2 | B3: F0 | C3: FR6700341 | D3: IT06100700 | F3: G000001238 | G3: Move | H3: =IFERROR(VLOOKUP(Table2[[#This Row], [Ticket]],Okey!A:B,2,0),"") -> ok | I3: completed | J3: MGF | M3: Joshua Cachola
A4: =1+A3 -> 3 | B4: F0 | C4: FR6700341 | D4: IT06100800 | F4: G000001239 | G4: Move | H4: =IFERROR(VLOOKUP(Table2[[#This Row], [Ticket]],Okey!A:B,2,0),"") -> ok | I4: completed | J4: MGF | M4: Joshua Cachola
A5: =1+A4 -> 4 | B5: F0 | C5: FR6711984 | D5: G000001096 | F5: G000000873 | G5: Move | H5: =IFERROR(VLOOKUP(Table2[[#This Row], [Ticket]],Okey!A:B,2,0),"") -> ok | I5: completed | J5: MGF | M5: Francesco Ricioppo
A6: =1+A5 -> 5 | B6: F0 | C6: FR6711984 | D6: G000000378 | F6: G000000873 | G6: Move | H6: =IFERROR(VLOOKUP(Table2[[#This Row], [Ticket]],Okey!A:B,2,0),"") -> ok | I6: completed | J6: MGF | M6: Francesco Ricioppo
A7: =1+A6 -> 6 | B7: F0 | C7: FR6711984 | D7: G000000869 | F7: G000000873 | G7: Move | H7: =IFERROR(VLOOKUP(Table2[[#This Row], [Ticket]],Okey!A:B,2,0),"") -> ok | I7: completed | J7: MGF | M7: Francesco Ricioppo
A8: =1+A7 -> 7 | B8: F0 | C8: FR6711984 | D8: G000000870 | F8: G000000873 | G8: Move | H8: =IFERROR(VLOOKUP(Table2[[#This Row], [Ticket]],Okey!A:B,2,0),"") -> ok | I8: completed | J8: MGF | M8: Francesco Ricioppo
A9: =1+A8 -> 8 | B9: F0 | C9: FR6711984 | D9: G000000871 | F9: G000000873 | G9: Move | H9: =IFERROR(VLOOKUP(Table2[[#This Row], [Ticket]],Okey!A:B,2,0),"") -> ok | I9: completed | J9: MGF | M9: Francesco Ricioppo
A10: =1+A9 -> 9 | B10: F0 | C10: FR6711984 | D10: G000000872 | F10: G000000873 | G10: Move | H10: =IFERROR(VLOOKUP(Table2[[#This Row], [Ticket]],Okey!A:B,2,0),"") -> ok | I10: completed | J10: MGF | M10: Francesco Ricioppo
A11: =1+A10 -> 10 | B11: F0 | C11: FR6711984 | D11: G000000464 | F11: G000000873 | G11: Move | H11: =IFERROR(VLOOKUP(Table2[[#This Row], [Ticket]],Okey!A:B,2,0),"") -> ok | I11: completed | J11: MGF | M11: Francesco Ricioppo
A12: =1+A11 -> 11 | B12: F0 | C12: FR6711984 | D12: G000000998 | F12: G000000873 | G12: Move | H12: =IFERROR(VLOOKUP(Table2[[#This Row], [Ticket]],Okey!A:B,2,0),"") -> ok | I12: completed | J12: MGF | M12: Francesco Ricioppo
A13: =1+A12 -> 12 | B13: F0 | C13: FR6711984 | D13: G000000996 | F13: G000000873 | G13: Move | H13: =IFERROR(VLOOKUP(Table2[[#This Row], [Ticket]],Okey!A:B,2,0),"") -> ok | I13: completed | J13: MGF | M13: Francesco Ricioppo
A14: =1+A13 -> 13 | B14: F0 | C14: FR6711984 | D14: G000000997 | F14: G000000873 | G14: Move | H14: =IFERROR(VLOOKUP(Table2[[#This Row], [Ticket]],Okey!A:B,2,0),"") -> ok | I14: completed | J14: MGF | M14: Francesco Ricioppo
A15: =1+A14 -> 14 | B15: F0 | C15: FR6712079 | D15: G000001020 | E15: FS Contractors DA | G15: Rename | H15: =IFERROR(VLOOKUP(Table2[[#This Row], [Ticket]],Okey!A:B,2,0),"") -> ok | I15: completed | J15: MGF | M15: Francesco Ricioppo
A16: =1+A15 -> 15 | B16: F0 | C16: FR6712079 | D16: G000001011 | E16: Contractors/Externals Area | F16: G000001020 | G16: Rename | H16: =IFERROR(VLOOKUP(Table2[[#This Row], [Ticket]],Okey!A:B,2,0),"") -> ok | I16: completed | J16: MGF | M16: Francesco Ricioppo
A17: =1+A16 -> 16 | B17: F0 | C17: FR6712079 | D17: G000001026 | E17: Z-Area | F17: G000001020 | G17: Rename | H17: =IFERROR(VLOOKUP(Table2[[#This Row], [Ticket]],Okey!A:B,2,0),"") -> ok | I17: completed | J17: MGF | M17: Francesco Ricioppo
A18: =1+A17 -> 17 | B18: F0 | C18: FR6712079 | D18: G000001010 | E18: W-Area | F18: G000001020 | G18: Rename | H18: =IFERROR(VLOOKUP(Table2[[#This Row], [Ticket]],Okey!A:B,2,0),"") -> ok | I18: completed | J18: MGF | M18: Francesco Ricioppo
A19: =1+A18 -> 18 | B19: F0 | C19: FR6736844 | D19: G000000398 | F19: G000000873 | G19: Move | H19: =IFERROR(VLOOKUP(Table2[[#This Row], [Ticket]],Okey!A:B,2,0),"") -> ok | I19: completed | J19: MGF | M19: Francesco Ricioppo
A20: =1+A19 -> 19 | B20: F0 | C20: FR6736844 | D20: G000000356 | F20: G000000873 | G20: Move | H20: =IFERROR(VLOOKUP(Table2[[#This Row], [Ticket]],Okey!A:B,2,0),"") -> ok | I20: completed | J20: MGF | M20: Francesco Ricioppo
A21: =1+A20 -> 20 | B21: F0 | C21: FR6736844 | D21: G000000357 | F21: G000000873 | G21: Move | H21: =IFERROR(VLOOKUP(Table2[[#This Row], [Ticket]],Okey!A:B,2,0),"") -> ok | I21: completed | J21: MGF | M21: Francesco Ricioppo
A22: =1+A21 -> 21 | B22: F0 | C22: FR6736844 | D22: G000000358 | F22: G000000873 | G22: Move | H22: =IFERROR(VLOOKUP(Table2[[#This Row], [Ticket]],Okey!A:B,2,0),"") -> ok | I22: completed | J22: MGF | M22: Francesco Ricioppo
A23: =1+A22 -> 22 | B23: F0 | C23: FR6736844 | D23: G000000399 | F23: G000000873 | G23: Move | H23: =IFERROR(VLOOKUP(Table2[[#This Row], [Ticket]],Okey!A:B,2,0),"") -> ok | I23: completed | J23: MGF | M23: Francesco Ricioppo
A24: =1+A23 -> 23 | B24: F0 | C24: FR6736844 | D24: G000000400 | F24: G000000873 | G24: Move | H24: =IFERROR(VLOOKUP(Table2[[#This Row], [Ticket]],Okey!A:B,2,0),"") -> ok | I24: completed | J24: MGF | M24: Francesco Ricioppo
A25: =1+A24 -> 24 | B25: F0 | C25: FR6736844 | D25: G000000401 | F25: G000000873 | G25: Move | H25: =IFERROR(VLOOKUP(Table2[[#This Row], [Ticket]],Okey!A:B,2,0),"") -> ok | I25: completed | J25: MGF | M25: Francesco Ricioppo
A26: =1+A25 -> 25 | B26: F0 | C26: FR6737570 | D26: G000000878 | E26: SM-SF/SC Fire Brigade & Security | G26: Rename | H26: =IFERROR(VLOOKUP(Table2[[#This Row], [Ticket]],Okey!A:B,2,0),"") -> ok | I26: completed | J26: MGF | M26: Francesco Ricioppo
A27: =1+A26 -> 26 | B27: F0 | C27: FR6737570 | D27: G000000435 | E27: SM-SF Fire Protection | F27: G000000878 | G27: Rename/Move | H27: =IFERROR(VLOOKUP(Table2[[#This Row], [Ticket]],Okey!A:B,2,0),"") -> ok | I27: completed | J27: MGF | M27: Francesco Ricioppo
A28: =1+A27 -> 27 | B28: F0 | C28: FR6737570 | D28: G000000436 | E28: SM-SC Site Security & Cross Services | F28: G000000878 | G28: Rename/Move | H28: =IFERROR(VLOOKUP(Table2[[#This Row], [Ticket]],Okey!A:B,2,0),"") -> ok | I28: completed | J28: MGF | M28: Francesco Ricioppo
A29: =1+A28 -> 28 | B29: F0 | C29: FR6762200 | D29: H000004388 | E29: GCD WBS elements | F29: H000000616 | G29: New | H29: =IFERROR(VLOOKUP(Table2[[#This Row], [Ticket]],Okey!A:B,2,0),"") -> ok | I29: completed | J29: HC | M29: Lena Brand
A30: =1+A29 -> 29 | B30: F0 | C30: FR6797793 | D30: P000001200 | E30: Separation Cost | F30: P000001198 | G30: New | H30: =IFERROR(VLOOKUP(Table2[[#This Row], [Ticket]],Okey!A:B,2,0),"") -> ok | I30: completed | J30: EL | M30: Eivy Denine Cruz
A31: =1+A30 -> 30 | B31: F0 | C31: FR6797793 | D31: P000001201 | E31: Set up of NewCos | F31: P000001200 | G31: New | H31: =IFERROR(VLOOKUP(Table2[[#This Row], [Ticket]],Okey!A:B,2,0),"") -> ok | I31: completed | J31: EL | M31: Eivy Denine Cruz
A32: =1+A31 -> 31 | B32: F0 | C32: FR6797793 | D32: P000001202 | E32: Set up of Export Model & Hubs | F32: P000001200 | G32: New | H32: =IFERROR(VLOOKUP(Table2[[#This Row], [Ticket]],Okey!A:B,2,0),"") -> ok | I32: completed | J32: EL | M32: Eivy Denine Cruz
A33: =1+A32 -> 32 | B33: F0 | C33: FR6797793 | D33: P000001203 | E33: Physical separation | F33: P000001200 | G33: New | H33: =IFERROR(VLOOKUP(Table2[[#This Row], [Ticket]],Okey!A:B,2,0),"") -> ok | I33: completed | J33: EL | M33: Eivy Denine Cruz
A34: =1+A33 -> 33 | B34: F0 | C34: FR6797793 | D34: P000001204 | E34: Legal C/O of POG-8 & POG-3 out of current legal entities | F34: P000001200 | G34: New | H34: =IFERROR(VLOOKUP(Table2[[#This Row], [Ticket]],Okey!A:B,2,0),"") -> ok | I34: completed | J34: EL | M34: Eivy Denine Cruz
A35: =1+A34 -> 34 | B35: F0 | C35: FR6797793 | D35: P000001205 | E35: IT Separation | F35: P000001200 | G35: New | H35: =IFERROR(VLOOKUP(Table2[[#This Row], [Ticket]],Okey!A:B,2,0),"") -> ok | I35: completed | J35: EL | M35: Eivy Denine Cruz
A36: =1+A35 -> 35 | B36: F0 | C36: FR6797793 | D36: P000001206 | E36: Business Backfills | F36: P000001205 | G36: New | H36: =IFERROR(VLOOKUP(Table2[[#This Row], [Ticket]],Okey!A:B,2,0),"") -> ok | I36: completed | J36: EL | M36: Eivy Denine Cruz
A37: =1+A36 -> 36 | B37: F0 | C37: FR6797793 | D37: P000001207 | E37: MBS Backfills & support | F37: P000001205 | G37: New | H37: =IFERROR(VLOOKUP(Table2[[#This Row], [Ticket]],Okey!A:B,2,0),"") -> ok | I37: completed | J37: EL | M37: Eivy Denine Cruz
A38: =1+A37 -> 37 | B38: F0 | C38: FR6797793 | D38: P000001208 | E38: Additional Cost | F38: P000001198 | G38: New | H38: =IFERROR(VLOOKUP(Table2[[#This Row], [Ticket]],Okey!A:B,2,0),"") -> ok | I38: completed | J38: EL | M38: Eivy Denine Cruz
... A83: =1+A82 -> 82 | B83: F0 | C83: FR6797793 | D83: P000001253 | E83: Feasibility | F83: P000000593 | G83: New | H83: =IFERROR(VLOOKUP(Table2[[#This Row], [Ticket]],Okey!A:B,2,0),"") -> ok | I83: completed | J83: EL | M83: Eivy Denine Cruz
A84: =1+A83 -> 83 | B84: F0 | C84: FR6797793 | D84: P000000551 | F84: O000000009 | G84: Delete | H84: =IFERROR(VLOOKUP(Table2[[#This Row], [Ticket]],Okey!A:B,2,0),"") -> ok | I84: completed | J84: EL | M84: Eivy Denine Cruz
...

Sheet old
A1: No. | B1: Forecast? | C1: Ticket | D1: Node | E1: Name | F1: Parent | G1: Action | H1: STATUS | I1: STATUS Check | J1: Sector | K1: Comments | L1: SANITY | M1: Author
A2: 1 | B2: F1 | C2: FR6934915 | D2: G000000994 | F2: G000000529 | G2: Move | H2: =IFERROR(VLOOKUP(Table2[[#This Row], [Ticket]],Okey!A:B,2,0),"") -> ok | I2: completed | J2: MGF | M2: Francesco Ricioppo
A3: =1+A2 -> 2 | B3: F1 | C3: FR6934915 | D3: G000000995 | F3: G000000529 | G3: Move | H3: =IFERROR(VLOOKUP(Table2[[#This Row], [Ticket]],Okey!A:B,2,0),"") -> ok | I3: completed | J3: MGF | M3: Francesco Ricioppo
A4: =1+A3 -> 3 | B4: F1 | C4: FR6934915 | D4: G000000993 | F4: G000000873 | G4: Move | H4: =IFERROR(VLOOKUP(Table2[[#This Row], [Ticket]],Okey!A:B,2,0),"") -> ok | I4: completed | J4: MGF | M4: Francesco Ricioppo
A5: =1+A4 -> 4 | B5: F1 | C5: FR6952137 | D5: G000001357 | E5: MBS S&T Learning & Develop., Knwldg Mgt | F5: G000001146 | G5: New | H5: =IFERROR(VLOOKUP(Table2[[#This Row], [Ticket]],Okey!A:B,2,0),"") -> ok | I5: completed | J5: MGF | M5: Yvonne Doernhofer
A6: =1+A5 -> 5 | B6: F1 | C6: FR6952137 | D6: G000001191 | E6: MBS S&T - Business Process Management | G6: Rename | H6: =IFERROR(VLOOKUP(Table2[[#This Row], [Ticket]],Okey!A:B,2,0),"") -> ok | I6: completed | J6: MGF | M6: Yvonne Doernhofer
A7: =1+A6 -> 6 | B7: F1 | C7: FR6995596 | D7: G000000511 | F7: G000000873 | G7: Move | H7: =IFERROR(VLOOKUP(Table2[[#This Row], [Ticket]],Okey!A:B,2,0),"") -> ok | I7: completed | J7: MGF | M7: Francesco Ricioppo
A8: =1+A7 -> 7 | B8: F1 | C8: FR6995596 | D8: G000000512 | F8: G000000873 | G8: Move | H8: =IFERROR(VLOOKUP(Table2[[#This Row], [Ticket]],Okey!A:B,2,0),"") -> ok | I8: completed | J8: MGF | M8: Francesco Ricioppo
A9: =1+A8 -> 8 | B9: F1 | C9: FR6995596 | D9: G000000513 | F9: G000000873 | G9: Move | H9: =IFERROR(VLOOKUP(Table2[[#This Row], [Ticket]],Okey!A:B,2,0),"") -> ok | I9: completed | J9: MGF | M9: Francesco Ricioppo
A10: =1+A9 -> 9 | B10: F1 | C10: FR6995596 | D10: G000000514 | F10: G000000873 | G10: Move | H10: =IFERROR(VLOOKUP(Table2[[#This Row], [Ticket]],Okey!A:B,2,0),"") -> ok | I10: completed | J10: MGF | M10: Francesco Ricioppo
A11: =1+A10 -> 10 | B11: F1 | C11: FR6995596 | D11: G000001007 | F11: G000000873 | G11: Move | H11: =IFERROR(VLOOKUP(Table2[[#This Row], [Ticket]],Okey!A:B,2,0),"") -> ok | I11: completed | J11: MGF | M11: Francesco Ricioppo
A12: =1+A11 -> 11 | B12: F1 | C12: FR6995596 | D12: G000001065 | F12: G000000873 | G12: Move | H12: =IFERROR(VLOOKUP(Table2[[#This Row], [Ticket]],Okey!A:B,2,0),"") -> ok | I12: completed | J12: MGF | M12: Francesco Ricioppo
A13: =1+A12 -> 12 | B13: F1 | C13: FR6995596 | D13: G000001066 | F13: G000000873 | G13: Move | H13: =IFERROR(VLOOKUP(Table2[[#This Row], [Ticket]],Okey!A:B,2,0),"") -> ok | I13: completed | J13: MGF | M13: Francesco Ricioppo
A14: =1+A13 -> 13 | B14: F1 | C14: FR7010885 | D14: G000000392 | E14: SM-PT | G14: Rename | H14: =IFERROR(VLOOKUP(Table2[[#This Row], [Ticket]],Okey!A:B,2,0),"") -> ok | I14: completed | J14: MGF | M14: Marcus Morowski
A15: =1+A14 -> 14 | B15: F1 | C15: FR7010885 | D15: G000000389 | E15: SM-PM und PT | G15: Rename | H15: =IFERROR(VLOOKUP(Table2[[#This Row], [Ticket]],Okey!A:B,2,0),"") -> ok | I15: completed | J15: MGF | M15: Marcus Morowski
A16: =1+A15 -> 15 | B16: F1 | C16: FR7010885 | D16: G000000918 | E16: SM-PTT Material Management | G16: Rename | H16: =IFERROR(VLOOKUP(Table2[[#This Row], [Ticket]],Okey!A:B,2,0),"") -> ok | I16: completed | J16: MGF | M16: Marcus Morowski
A17: =1+A16 -> 16 | B17: F1 | C17: FR7010885 | D17: G000000919 | E17: SM-PTT Technical Warehouse | G17: Rename | H17: =IFERROR(VLOOKUP(Table2[[#This Row], [Ticket]],Okey!A:B,2,0),"") -> ok | I17: completed | J17: MGF | M17: Marcus Morowski
A18: =1+A17 -> 17 | B18: F1 | C18: FR7010885 | D18: G000000919 | E18: SM-PTT IVV Allocation CCs | G18: Rename | H18: =IFERROR(VLOOKUP(Table2[[#This Row], [Ticket]],Okey!A:B,2,0),"") -> ok | I18: completed | J18: MGF | K18: WTF, duplicated | M18: Marcus Morowski
A19: =1+A18 -> 18 | B19: F1 | C19: FR7010885 | D19: G000000387 | E19: SM-PM | F19: G000000389 | G19: Rename/Move | H19: =IFERROR(VLOOKUP(Table2[[#This Row], [Ticket]],Okey!A:B,2,0),"") -> ok | I19: completed | J19: MGF | M19: Marcus Morowski
A20: =1+A19 -> 19 | B20: F1 | C20: FR7010885 | D20: G000000391 | E20: SM-PMA | F20: G000000387 | G20: Rename/Move | H20: =IFERROR(VLOOKUP(Table2[[#This Row], [Ticket]],Okey!A:B,2,0),"") -> ok | I20: completed | J20: MGF | M20: Marcus Morowski
A21: =1+A20 -> 20 | B21: F1 | C21: FR7015139 | D21: P000000196 | E21: PG1 Blending+Packaging | G21: Rename | H21: =IFERROR(VLOOKUP(Table2[[#This Row], [Ticket]],Okey!A:B,2,0),"") -> ok | I21: completed | J21: EL | M21: Gerhard Doeller
A22: =1+A21 -> 21 | B22: F1 | C22: FR7015139 | D22: P000000197 | E22: PG2 Coating | G22: Rename | H22: =IFERROR(VLOOKUP(Table2[[#This Row], [Ticket]],Okey!A:B,2,0),"") -> ok | I22: completed | J22: EL | M22: Gerhard Doeller
A23: =1+A22 -> 22 | B23: F1 | C23: FR7015139 | D23: P000000198 | E23: PG1 Substrates | G23: Rename | H23: =IFERROR(VLOOKUP(Table2[[#This Row], [Ticket]],Okey!A:B,2,0),"") -> ok | I23: completed | J23: EL | M23: Gerhard Doeller
A24: =1+A23 -> 23 | B24: F1 | C24: FR7037412 | D24: L000013817 | E24: Business Integration _GPO | F24: L000013445 | G24: New | H24: =IFERROR(VLOOKUP(Table2[[#This Row], [Ticket]],Okey!A:B,2,0),"") -> ok | I24: completed | J24: LS | M24: Jayson Martinez
A25: =1+A24 -> 24 | B25: F1 | C25: FR7037412 | D25: L000013818 | E25: Business Integration _PS VS | F25: L000013417 | G25: New | H25: =IFERROR(VLOOKUP(Table2[[#This Row], [Ticket]],Okey!A:B,2,0),"") -> ok | I25: completed | J25: LS | M25: Jayson Martinez
A26: =1+A25 -> 25 | B26: F1 | C26: FR7037412 | D26: L000013819 | E26: mRNA and LNP Innovation | F26: L000006420 | G26: New | H26: =IFERROR(VLOOKUP(Table2[[#This Row], [Ticket]],Okey!A:B,2,0),"") -> ok | I26: completed | J26: LS | M26: Jayson Martinez
A27: =1+A26 -> 26 | B27: F1 | C27: FR7037412 | D27: L000013820 | E27: Bioconujation and SM Innovation | F27: L000006420 | G27: New | H27: =IFERROR(VLOOKUP(Table2[[#This Row], [Ticket]],Okey!A:B,2,0),"") -> ok | I27: completed | J27: LS | M27: Jayson Martinez
A28: =1+A27 -> 27 | B28: F1 | C28: FR7037412 | D28: L000013821 | E28: Viral Vectors Innovation | F28: L000013174 | G28: New | H28: =IFERROR(VLOOKUP(Table2[[#This Row], [Ticket]],Okey!A:B,2,0),"") -> ok | I28: completed | J28: LS | M28: Jayson Martinez
A29: =1+A28 -> 28 | B29: F1 | C29: FR7037412 | D29: L000013822 | E29: Biologics Innovation | F29: L000013174 | G29: New | H29: =IFERROR(VLOOKUP(Table2[[#This Row], [Ticket]],Okey!A:B,2,0),"") -> ok | I29: completed | J29: LS | M29: Jayson Martinez
A30: =1+A29 -> 29 | B30: F1 | C30: FR7037412 | D30: L000013823 | E30: PMO CDMO Innovation | F30: L000013785 | G30: New | H30: =IFERROR(VLOOKUP(Table2[[#This Row], [Ticket]],Okey!A:B,2,0),"") -> ok | I30: completed | J30: LS | M30: Jayson Martinez
A31: =1+A30 -> 30 | B31: F1 | C31: FR7037412 | D31: L000005722 | E31: BM - Comm NA - South Pharma | G31: Rename | H31: =IFERROR(VLOOKUP(Table2[[#This Row], [Ticket]],Okey!A:B,2,0),"") -> ok | I31: completed | J31: LS | M31: Jayson Martinez
A32: =1+A31 -> 31 | B32: F1 | C32: FR7037412 | D32: L000013350 | E32: CDMO - APAC Sales | G32: Rename | H32: =IFERROR(VLOOKUP(Table2[[#This Row], [Ticket]],Okey!A:B,2,0),"") -> ok | I32: completed | J32: LS | M32: Jayson Martinez
A33: =1+A32 -> 32 | B33: F1 | C33: FR7037412 | D33: L000006425 | E33: Synthesis mRNA delivery & PEG's | F33: L000013819 | G33: Rename/Move | H33: =IFERROR(VLOOKUP(Table2[[#This Row], [Ticket]],Okey!A:B,2,0),"") -> ok | I33: completed | J33: LS | M33: Jayson Martinez
A34: =1+A33 -> 33 | B34: F1 | C34: FR7037412 | D34: L000006429 | E34: mRNA Delivery / Manufacturing | F34: L000013819 | G34: Rename/Move | H34: =IFERROR(VLOOKUP(Table2[[#This Row], [Ticket]],Okey!A:B,2,0),"") -> ok | I34: completed | J34: LS | M34: Jayson Martinez
A35: =1+A34 -> 34 | B35: F1 | C35: FR7037412 | D35: L000006431 | E35: ADC Payload Automation & Digital | F35: L000013820 | G35: Rename/Move | H35: =IFERROR(VLOOKUP(Table2[[#This Row], [Ticket]],Okey!A:B,2,0),"") -> ok | I35: completed | J35: LS | M35: Jayson Martinez
A36: =1+A35 -> 35 | B36: F1 | C36: FR7037412 | D36: L000011451 | E36: ADC Bionconjugation Template | F36: L000013820 | G36: Rename/Move | H36: =IFERROR(VLOOKUP(Table2[[#This Row], [Ticket]],Okey!A:B,2,0),"") -> ok | I36: completed | J36: LS | M36: Jayson Martinez
A37: =1+A36 -> 36 | B37: F1 | C37: FR7037412 | D37: L000007087 | E37: VV Innovation | F37: L000013821 | G37: Rename/Move | H37: =IFERROR(VLOOKUP(Table2[[#This Row], [Ticket]],Okey!A:B,2,0),"") -> ok | I37: completed | J37: LS | M37: Jayson Martinez
A38: =1+A37 -> 37 | B38: F1 | C38: FR7037412 | D38: L000006414 | E38: Synthesis & ADC CDMO Management | F38: L000013789 | G38: Rename/Move | H38: =IFERROR(VLOOKUP(Table2[[#This Row], [Ticket]],Okey!A:B,2,0),"") -> ok | I38: completed | J38: LS | M38: Jayson Martinez
A39: =1+A38 -> 38 | B39: F1 | C39: FR7037412 | D39: L000013151 | E39: CDMO Operations | F39: L000009201 | G39: Rename/Move | H39: =IFERROR(VLOOKUP(Table2[[#This Row], [Ticket]],Okey!A:B,2,0),"") -> ok | I39: completed | J39: LS | M39: Jayson Martinez
A40: =1+A39 -> 39 | B40: F1 | C40: FR7037412 | D40: L000013152 | E40: SAC BP & Implementation | F40: L000013789 | G40: Rename/Move | H40: =IFERROR(VLOOKUP(Table2[[#This Row], [Ticket]],Okey!A:B,2,0),"") -> ok | I40: completed | J40: LS | M40: Jayson Martinez
...

Sheet Sectors
A1: P | B1: Electronics
A2: L | B2: Life Science
A3: H | B3: Healthcare
A4: G | B4: MGF
A5: O | B5: No known

Sheet KPI
A2: STATUS | B2: (All)
A4: Count of No. | B4: Column Labels
B5: F0 | G5: F0 Total | H5: F1 | M5: F1 Total | N5: F2 | O5: F2 Total | P5: Grand Total
A6: Row Labels | B6: Delete | C6: Move | D6: New | E6: Rename | F6: Rename/Move | H6: Delete | I6: Move | J6: New | K6: Rename | L6: Rename/Move | N6: Move
A7: MGF | B7: 3 | C7: 40 | D7: 79 | E7: 10 | F7: 2 | G7: 134 | I7: 30 | J7: 4 | K7: 6 | L7: 2 | M7: 42 | N7: 7 | O7: 7 | P7: 183
A8: LS | B8: 8 | C8: 35 | D8: 27 | E8: 10 | F8: 2 | G8: 82 | I8: 18 | J8: 7 | K8: 2 | L8: 15 | M8: 42 | P8: 124
A9: HC | B9: 4 | D9: 6 | E9: 8 | G9: 18 | P9: 18
A10: EL | B10: 1 | D10: 54 | G10: 55 | H10: 16 | I10: 1 | J10: 14 | K10: 93 | M10: 124 | P10: 179
A11: Grand Total | B11: 16 | C11: 75 | D11: 166 | E11: 28 | F11: 4 | G11: 289 | H11: 16 | I11: 49 | J11: 25 | K11: 101 | L11: 17 | M11: 208 | N11: 7 | O11: 7 | P11: 504
